Workbook
Name XMidpoint: '2025 Scatter Data'!$H$22
Name YMidpoint: '2025 Scatter Data'!$K$22

Sheet 2025 Season All
A1: SEASON TOTAL
A3: Team | B3: Ball Winning | M3: Ball Movement | X3: Scoring | AI3: Defence | AT3: Pressure | BE3: Health Check | BT3: Wheelo Ratings
B4: Post Clear CP Diff | C4: Rank | D4: Ground Ball Diff | E4: Rank | F4: 1st Poss to Clear % | G4: Rank | H4: Clearance Diff | I4: Rank | J4: Ball Winning Ranking | K4: Rank | M4: Def Half to Score % | N4: Rank | O4: Chain to Score % | P4: Rank | Q4: D50 to F50 % | R4: Rank | S4: Kick Rating | T4: Rank | U4: Ball Movement Ranking | V4: Rank | X4: Scores per I50 % | Y4: Rank | Z4: Goals Per I 50 % | AA4: Rank | AB4: Accuracy % | AC4: Rank | AD4: +/- Exp Score | AE4: Rank | AF4: Scoring Ranking | AG4: Rank | AI4: Def Half to Score Ag % | AJ4: Rank | AK4: Chain to Score Ag % | AL4: Rank | AM4: D50 to F50 Ag % | AN4: Rank | AO4: Goals Per I50 Ag % | AP4: Rank | AQ4: Defence Ranking | AR4: Rank | AT4: Tackle Diff | AU4: Rank | AV4: F50 Tackles | AW4: Rank | AX4: Pressure Acts | AY4: Rank | AZ4: 1%'ers | BA4: Rank | BB4: Pressure Ranking | BC4: Rank | BE4: Score from Turnover For | BF4: Rank | BG4: Scores from Turnover Ag | BH4: Rank | BI4: Scores from Stoppages For | BJ4: Rank | BK4: Scores from Stoppage Ag | BL4: Rank | BM4: Territory % | BN4: Rank | BO4: Post-Clearance CP Diff | BP4: Rank | BQ4: Health Check Ranking | BR4: Rank | BT4: Attack Rating | BU4: Rank | BV4: Defence Rating | BW4: Rank | BX4: Overall Rating | BY4: Rank
A5: Adelaide | B5: =VLOOKUP($A5,'2025'!$A:$IZ,222,FALSE) -> 7.08 | C5: =RANK(B5,B$5:B$22) -> 1 | D5: =VLOOKUP($A5,'2025'!$A:$IZ,218,FALSE) -> -0.96 | E5: =RANK(D5,D$5:D$22) -> 12 | F5: =VLOOKUP($A5,'2025'!$A:$IZ,49,FALSE) -> 76.529 | G5: =RANK(F5,F$5:F$22) -> 4 | H5: =VLOOKUP($A5,'2025'!$A:$IZ,229,FALSE) -> -1.88 | I5: =RANK(H5,H$5:H$22) -> 12 | J5: =104-(C5+E5+G5+I5) -> 75 | K5: =RANK(J5,J$5:J$22) -> 5 | M5: =VLOOKUP($A5,'2025'!$A:$IZ,88,FALSE) -> 12.764 | N5: =RANK(M5,M$5:M$22) -> 10 | O5: =VLOOKUP($A5,'2025'!$A:$IZ,84,FALSE) -> 20.703 | P5: =RANK(O5,O$5:O$22) -> 11 | Q5: =VLOOKUP($A5,'2025'!$A:$IZ,85,FALSE) -> 21.095 | R5: =RANK(Q5,Q$5:Q$22) -> 12 | S5: =VLOOKUP($A5,'2025'!$A:$IZ,29,FALSE) -> 2.136 | T5: =RANK(S5,S$5:S$22) -> 5 | U5: =104-(N5+P5+R5+T5) -> 66 | V5: =RANK(U5,U$5:U$22) -> 10 | X5: =VLOOKUP($A5,'2025'!$A:$IZ,65,FALSE) -> 46.033 | Y5: =RANK(X5,X$5:X$22) -> 4 | Z5: =VLOOKUP($A5,'2025'!$A:$IZ,64,FALSE) -> 26.722 | AA5: =RANK(Z5,Z$5:Z$22) -> 3 | AB5: =VLOOKUP($A5,'2025'!$A:$IZ,63,FALSE) -> 52.5 | AC5: =RANK(AB5,AB$5:AB$22) -> 2 | AD5: =VLOOKUP($A5,'2025'!$A:$IZ,71,FALSE) -> 6.067 | AE5: =RANK(AD5,AD$5:AD$22) -> 1 | AF5: =104-(Y5+AA5+AC5+AE5) -> 94 | AG5: =RANK(AF5,AF$5:AF$22) -> 2 | AI5: =VLOOKUP($A5,'2025'!$A:$IZ,183,FALSE) -> 7.039 | AJ5: =RANK(AI5,AI$5:AI$22,1) -> 1 | AK5: =VLOOKUP($A5,'2025'!$A:$IZ,181,FALSE) -> 17.787 | AL5: =RANK(AK5,AK$5:AK$22,1) -> 2 | AM5: =VLOOKUP($A5,'2025'!$A:$IZ,182,FALSE) -> 18.201 | AN5: =RANK(AM5,AM$5:AM$22,1) -> 1 | AO5: =VLOOKUP($A5,'2025'!$A:$IZ,163,FALSE) -> 20.346 | AP5: =RANK(AO5,AO$5:AO$22,1) -> 1 | AQ5: =104-(AJ5+AL5+AN5+AP5) -> 99 | AR5: =RANK(AQ5,AQ$5:AQ$22) -> 1 | AT5: =VLOOKUP($A5,'2025'!$A:$IZ,250,FALSE) -> 3.72 | AU5: =RANK(AT5,AT$5:AT$22,0) -> 4 | AV5: =VLOOKUP($A5,'2025'!$A:$IZ,92,FALSE) -> 9.72 | AW5: =RANK(AV5,AV$5:AV$22,0) -> 16 | AX5: =VLOOKUP($A5,'2025'!$A:$IZ,93,FALSE) -> 270.88 | AY5: =RANK(AX5,AX$5:AX$22,0) -> 7 | AZ5: =VLOOKUP($A5,'2025'!$A:$IZ,108,FALSE) -> 43.96 | BA5: =RANK(AZ5,AZ$5:AZ$22,0) -> 5 | BB5: =104-(AU5+AW5+AY5+BA5) -> 72 | BC5: =RANK(BB5,BB$5:BB$22) -> 6 | BE5: =VLOOKUP($A5,'2025'!$A:$IZ,80,FALSE) -> 57.6 | BF5: =RANK(BE5,BE$5:BE$22) -> 2 | BG5: =VLOOKUP($A5,'2025'!$A:$IZ,177,FALSE) -> 40.72 | BH5: =RANK(BG5,BG$5:BG$22,1) -> 3 | BI5: =VLOOKUP($A5,'2025'!$A:$IZ,79,FALSE) -> 34.36 | BJ5: =RANK(BI5,BI$5:BI$22) -> 8 | BK5: =VLOOKUP($A5,'2025'!$A:$IZ,176,FALSE) -> 28.8 | BL5: =RANK(BK5,BK$5:BK$22,1) -> 1 | BM5: =VLOOKUP($A5,'2025'!$A:$IZ,11,FALSE) -> 50.839 | BN5: =RANK(BM5,BM$5:BM$22) -> 9 | BO5: =VLOOKUP($A5,'2025'!$A:$IZ,222,FALSE) -> 7.08 | BP5: =RANK(BO5,BO$5:BO$22) -> 1 | BQ5: =106-(BF5+BH5+BN5+BP5+BJ5+BL5) -> 82 | BR5: =RANK(BQ5,BQ$5:BQ$22) -> 3 | BT5: =VLOOKUP($A5,'Ratings Season'!$A:$M,10,FALSE) -> 9.4 | BU5: =RANK(BT5,BT$5:BT$22) -> 3 | BV5: =VLOOKUP($A5,'Ratings Season'!$A:$M,12,FALSE) -> 8.9 | BW5: =RANK(BV5,BV$5:BV$22) -> 4 | BX5: =VLOOKUP($A5,'Ratings Season'!$A:$M,8,FALSE) -> 18.2 | BY5: =RANK(BX5,BX$5:BX$22) -> 4
A6: Brisbane | B6: =VLOOKUP($A6,'2025'!$A:$IZ,222,FALSE) -> -0.852 | C6: =RANK(B6,B$5:B$22) -> 12 | D6: =VLOOKUP($A6,'2025'!$A:$IZ,218,FALSE) -> 3.556 | E6: =RANK(D6,D$5:D$22) -> 4 | F6: =VLOOKUP($A6,'2025'!$A:$IZ,49,FALSE) -> 76.636 | G6: =RANK(F6,F$5:F$22) -> 3 | H6: =VLOOKUP($A6,'2025'!$A:$IZ,229,FALSE) -> 5.259 | I6: =RANK(H6,H$5:H$22) -> 2 | J6: =104-(C6+E6+G6+I6) -> 83 | K6: =RANK(J6,J$5:J$22) -> 2 | M6: =VLOOKUP($A6,'2025'!$A:$IZ,88,FALSE) -> 14.914 | N6: =RANK(M6,M$5:M$22) -> 3 | O6: =VLOOKUP($A6,'2025'!$A:$IZ,84,FALSE) -> 22.226 | P6: =RANK(O6,O$5:O$22) -> 4 | Q6: =VLOOKUP($A6,'2025'!$A:$IZ,85,FALSE) -> 26.347 | R6: =RANK(Q6,Q$5:Q$22) -> 3 | S6: =VLOOKUP($A6,'2025'!$A:$IZ,29,FALSE) -> 1.716 | T6: =RANK(S6,S$5:S$22) -> 7 | U6: =104-(N6+P6+R6+T6) -> 87 | V6: =RANK(U6,U$5:U$22) -> 3 | X6: =VLOOKUP($A6,'2025'!$A:$IZ,65,FALSE) -> 44.488 | Y6: =RANK(X6,X$5:X$22) -> 10 | Z6: =VLOOKUP($A6,'2025'!$A:$IZ,64,FALSE) -> 23.157 | AA6: =RANK(Z6,Z$5:Z$22) -> 11 | AB6: =VLOOKUP($A6,'2025'!$A:$IZ,63,FALSE) -> 46.588 | AC6: =RANK(AB6,AB$5:AB$22) -> 12 | AD6: =VLOOKUP($A6,'2025'!$A:$IZ,71,FALSE) -> -1.863 | AE6: =RANK(AD6,AD$5:AD$22) -> 15 | AF6: =104-(Y6+AA6+AC6+AE6) -> 56 | AG6: =RANK(AF6,AF$5:AF$22) -> 11 | AI6: =VLOOKUP($A6,'2025'!$A:$IZ,183,FALSE) -> 9.122 | AJ6: =RANK(AI6,AI$5:AI$22,1) -> 9 | AK6: =VLOOKUP($A6,'2025'!$A:$IZ,181,FALSE) -> 19.476 | AL6: =RANK(AK6,AK$5:AK$22,1) -> 7 | AM6: =VLOOKUP($A6,'2025'!$A:$IZ,182,FALSE) -> 24.441 | AN6: =RANK(AM6,AM$5:AM$22,1) -> 14 | AO6: =VLOOKUP($A6,'2025'!$A:$IZ,163,FALSE) -> 22.657 | AP6: =RANK(AO6,AO$5:AO$22,1) -> 7 | AQ6: =104-(AJ6+AL6+AN6+AP6) -> 67 | AR6: =RANK(AQ6,AQ$5:AQ$22) -> 12 | AT6: =VLOOKUP($A6,'2025'!$A:$IZ,250,FALSE) -> 1.778 | AU6: =RANK(AT6,AT$5:AT$22,0) -> 7 | AV6: =VLOOKUP($A6,'2025'!$A:$IZ,92,FALSE) -> 11.704 | AW6: =RANK(AV6,AV$5:AV$22,0) -> 4 | AX6: =VLOOKUP($A6,'2025'!$A:$IZ,93,FALSE) -> 265.407 | AY6: =RANK(AX6,AX$5:AX$22,0) -> 12 | AZ6: =VLOOKUP($A6,'2025'!$A:$IZ,108,FALSE) -> 46.407 | BA6: =RANK(AZ6,AZ$5:AZ$22,0) -> 2 | BB6: =104-(AU6+AW6+AY6+BA6) -> 79 | BC6: =RANK(BB6,BB$5:BB$22) -> 2 | BE6: =VLOOKUP($A6,'2025'!$A:$IZ,80,FALSE) -> 52.111 | BF6: =RANK(BE6,BE$5:BE$22) -> 4 | BG6: =VLOOKUP($A6,'2025'!$A:$IZ,177,FALSE) -> 40.815 | BH6: =RANK(BG6,BG$5:BG$22,1) -> 4 | BI6: =VLOOKUP($A6,'2025'!$A:$IZ,79,FALSE) -> 35.296 | BJ6: =RANK(BI6,BI$5:BI$22) -> 7 | BK6: =VLOOKUP($A6,'2025'!$A:$IZ,176,FALSE) -> 33.185 | BL6: =RANK(BK6,BK$5:BK$22,1) -> 11 | BM6: =VLOOKUP($A6,'2025'!$A:$IZ,11,FALSE) -> 51.175 | BN6: =RANK(BM6,BM$5:BM$22) -> 6 | BO6: =VLOOKUP($A6,'2025'!$A:$IZ,222,FALSE) -> -0.852 | BP6: =RANK(BO6,BO$5:BO$22) -> 12 | BQ6: =106-(BF6+BH6+BN6+BP6+BJ6+BL6) -> 62 | BR6: =RANK(BQ6,BQ$5:BQ$22) -> 6 | BT6: =VLOOKUP($A6,'Ratings Season'!$A:$M,10,FALSE) -> 9.2 | BU6: =RANK(BT6,BT$5:BT$22) -> 4 | BV6: =VLOOKUP($A6,'Ratings Season'!$A:$M,12,FALSE) -> 9.7 | BW6: =RANK(BV6,BV$5:BV$22) -> 2 | BX6: =VLOOKUP($A6,'Ratings Season'!$A:$M,8,FALSE) -> 18.8 | BY6: =RANK(BX6,BX$5:BX$22) -> 3
A7: Carlton | B7: =VLOOKUP($A7,'2025'!$A:$IZ,222,FALSE) -> 2.565 | C7: =RANK(B7,B$5:B$22) -> 5 | D7: =VLOOKUP($A7,'2025'!$A:$IZ,218,FALSE) -> 2.913 | E7: =RANK(D7,D$5:D$22) -> 5 | F7: =VLOOKUP($A7,'2025'!$A:$IZ,49,FALSE) -> 73.099 | G7: =RANK(F7,F$5:F$22) -> 15 | H7: =VLOOKUP($A7,'2025'!$A:$IZ,229,FALSE) -> 3.609 | I7: =RANK(H7,H$5:H$22) -> 3 | J7: =104-(C7+E7+G7+I7) -> 76 | K7: =RANK(J7,J$5:J$22) -> 4 | M7: =VLOOKUP($A7,'2025'!$A:$IZ,88,FALSE) -> 11.828 | N7: =RANK(M7,M$5:M$22) -> 13 | O7: =VLOOKUP($A7,'2025'!$A:$IZ,84,FALSE) -> 19.429 | P7: =RANK(O7,O$5:O$22) -> 13 | Q7: =VLOOKUP($A7,'2025'!$A:$IZ,85,FALSE) -> 25.68 | R7: =RANK(Q7,Q$5:Q$22) -> 4 | S7: =VLOOKUP($A7,'2025'!$A:$IZ,29,FALSE) -> -0.947 | T7: =RANK(S7,S$5:S$22) -> 16 | U7: =104-(N7+P7+R7+T7) -> 58 | V7: =RANK(U7,U$5:U$22) -> 13 | X7: =VLOOKUP($A7,'2025'!$A:$IZ,65,FALSE) -> 40.876 | Y7: =RANK(X7,X$5:X$22) -> 16 | Z7: =VLOOKUP($A7,'2025'!$A:$IZ,64,FALSE) -> 21.006 | AA7: =RANK(Z7,Z$5:Z$22) -> 15 | AB7: =VLOOKUP($A7,'2025'!$A:$IZ,63,FALSE) -> 46.92 | AC7: =RANK(AB7,AB$5:AB$22) -> 10 | AD7: =VLOOKUP($A7,'2025'!$A:$IZ,71,FALSE) -> -1.806 | AE7: =RANK(AD7,AD$5:AD$22) -> 14 | AF7: =104-(Y7+AA7+AC7+AE7) -> 49 | AG7: =RANK(AF7,AF$5:AF$22) -> 14 | AI7: =VLOOKUP($A7,'2025'!$A:$IZ,183,FALSE) -> 8.559 | AJ7: =RANK(AI7,AI$5:AI$22,1) -> 3 | AK7: =VLOOKUP($A7,'2025'!$A:$IZ,181,FALSE) -> 19.364 | AL7: =RANK(AK7,AK$5:AK$22,1) -> 6 | AM7: =VLOOKUP($A7,'2025'!$A:$IZ,182,FALSE) -> 22.002 | AN7: =RANK(AM7,AM$5:AM$22,1) -> 8 | AO7: =VLOOKUP($A7,'2025'!$A:$IZ,163,FALSE) -> 24.421 | AP7: =RANK(AO7,AO$5:AO$22,1) -> 11 | AQ7: =104-(AJ7+AL7+AN7+AP7) -> 76 | AR7: =RANK(AQ7,AQ$5:AQ$22) -> 6 | AT7: =VLOOKUP($A7,'2025'!$A:$IZ,250,FALSE) -> 0.217 | AU7: =RANK(AT7,AT$5:AT$22,0) -> 10 | AV7: =VLOOKUP($A7,'2025'!$A:$IZ,92,FALSE) -> 11.652 | AW7: =RANK(AV7,AV$5:AV$22,0) -> 6 | AX7: =VLOOKUP($A7,'2025'!$A:$IZ,93,FALSE) -> 272.217 | AY7: =RANK(AX7,AX$5:AX$22,0) -> 6 | AZ7: =VLOOKUP($A7,'2025'!$A:$IZ,108,FALSE) -> 43.217 | BA7: =RANK(AZ7,AZ$5:AZ$22,0) -> 8 | BB7: =104-(AU7+AW7+AY7+BA7) -> 74 | BC7: =RANK(BB7,BB$5:BB$22) -> 4 | BE7: =VLOOKUP($A7,'2025'!$A:$IZ,80,FALSE) -> 42.696 | BF7: =RANK(BE7,BE$5:BE$22) -> 13 | BG7: =VLOOKUP($A7,'2025'!$A:$IZ,177,FALSE) -> 44.087 | BH7: =RANK(BG7,BG$5:BG$22,1) -> 8 | BI7: =VLOOKUP($A7,'2025'!$A:$IZ,79,FALSE) -> 32.304 | BJ7: =RANK(BI7,BI$5:BI$22) -> 12 | BK7: =VLOOKUP($A7,'2025'!$A:$IZ,176,FALSE) -> 32.043 | BL7: =RANK(BK7,BK$5:BK$22,1) -> 7 | BM7: =VLOOKUP($A7,'2025'!$A:$IZ,11,FALSE) -> 51.102 | BN7: =RANK(BM7,BM$5:BM$22) -> 7 | BO7: =VLOOKUP($A7,'2025'!$A:$IZ,222,FALSE) -> 2.565 | BP7: =RANK(BO7,BO$5:BO$22) -> 5 | BQ7: =106-(BF7+BH7+BN7+BP7+BJ7+BL7) -> 54 | BR7: =RANK(BQ7,BQ$5:BQ$22) -> 8 | BT7: =VLOOKUP($A7,'Ratings Season'!$A:$M,10,FALSE) -> -6.7 | BU7: =RANK(BT7,BT$5:BT$22) -> 14 | BV7: =VLOOKUP($A7,'Ratings Season'!$A:$M,12,FALSE) -> 4.1 | BW7: =RANK(BV7,BV$5:BV$22) -> 8 | BX7: =VLOOKUP($A7,'Ratings Season'!$A:$M,8,FALSE) -> -2.6 | BY7: =RANK(BX7,BX$5:BX$22) -> 10
A8: Collingwood | B8: =VLOOKUP($A8,'2025'!$A:$IZ,222,FALSE) -> -1.4 | C8: =RANK(B8,B$5:B$22) -> 13 | D8: =VLOOKUP($A8,'2025'!$A:$IZ,218,FALSE) -> -6.16 | E8: =RANK(D8,D$5:D$22) -> 16 | F8: =VLOOKUP($A8,'2025'!$A:$IZ,49,FALSE) -> 72.271 | G8: =RANK(F8,F$5:F$22) -> 17 | H8: =VLOOKUP($A8,'2025'!$A:$IZ,229,FALSE) -> -2.16 | I8: =RANK(H8,H$5:H$22) -> 14 | J8: =104-(C8+E8+G8+I8) -> 44 | K8: =RANK(J8,J$5:J$22) -> 15 | M8: =VLOOKUP($A8,'2025'!$A:$IZ,88,FALSE) -> 12.692 | N8: =RANK(M8,M$5:M$22) -> 11 | O8: =VLOOKUP($A8,'2025'!$A:$IZ,84,FALSE) -> 21.47 | P8: =RANK(O8,O$5:O$22) -> 5 | Q8: =VLOOKUP($A8,'2025'!$A:$IZ,85,FALSE) -> 21.922 | R8: =RANK(Q8,Q$5:Q$22) -> 10 | S8: =VLOOKUP($A8,'2025'!$A:$IZ,29,FALSE) -> -0.004 | T8: =RANK(S8,S$5:S$22) -> 11 | U8: =104-(N8+P8+R8+T8) -> 67 | V8: =RANK(U8,U$5:U$22) -> 9 | X8: =VLOOKUP($A8,'2025'!$A:$IZ,65,FALSE) -> 45.256 | Y8: =RANK(X8,X$5:X$22) -> 6 | Z8: =VLOOKUP($A8,'2025'!$A:$IZ,64,FALSE) -> 23.193 | AA8: =RANK(Z8,Z$5:Z$22) -> 10 | AB8: =VLOOKUP($A8,'2025'!$A:$IZ,63,FALSE) -> 46.88 | AC8: =RANK(AB8,AB$5:AB$22) -> 11 | AD8: =VLOOKUP($A8,'2025'!$A:$IZ,71,FALSE) -> 0.577 | AE8: =RANK(AD8,AD$5:AD$22) -> 7 | AF8: =104-(Y8+AA8+AC8+AE8) -> 70 | AG8: =RANK(AF8,AF$5:AF$22) -> 8 | AI8: =VLOOKUP($A8,'2025'!$A:$IZ,183,FALSE) -> 9.481 | AJ8: =RANK(AI8,AI$5:AI$22,1) -> 12 | AK8: =VLOOKUP($A8,'2025'!$A:$IZ,181,FALSE) -> 17.353 | AL8: =RANK(AK8,AK$5:AK$22,1) -> 1 | AM8: =VLOOKUP($A8,'2025'!$A:$IZ,182,FALSE) -> 22.388 | AN8: =RANK(AM8,AM$5:AM$22,1) -> 10 | AO8: =VLOOKUP($A8,'2025'!$A:$IZ,163,FALSE) -> 21.423 | AP8: =RANK(AO8,AO$5:AO$22,1) -> 4 | AQ8: =104-(AJ8+AL8+AN8+AP8) -> 77 | AR8: =RANK(AQ8,AQ$5:AQ$22) -> 5 | AT8: =VLOOKUP($A8,'2025'!$A:$IZ,250,FALSE) -> 12.44 | AU8: =RANK(AT8,AT$5:AT$22,0) -> 1 | AV8: =VLOOKUP($A8,'2025'!$A:$IZ,92,FALSE) -> 13 | AW8: =RANK(AV8,AV$5:AV$22,0) -> 2 | AX8: =VLOOKUP($A8,'2025'!$A:$IZ,93,FALSE) -> 274.68 | AY8: =RANK(AX8,AX$5:AX$22,0) -> 4 | AZ8: =VLOOKUP($A8,'2025'!$A:$IZ,108,FALSE) -> 44.56 | BA8: =RANK(AZ8,AZ$5:AZ$22,0) -> 4 | BB8: =104-(AU8+AW8+AY8+BA8) -> 93 | BC8: =RANK(BB8,BB$5:BB$22) -> 1 | BE8: =VLOOKUP($A8,'2025'!$A:$IZ,80,FALSE) -> 51.36 | BF8: =RANK(BE8,BE$5:BE$22) -> 5 | BG8: =VLOOKUP($A8,'2025'!$A:$IZ,177,FALSE) -> 34.84 | BH8: =RANK(BG8,BG$5:BG$22,1) -> 1 | BI8: =VLOOKUP($A8,'2025'!$A:$IZ,79,FALSE) -> 31.6 | BJ8: =RANK(BI8,BI$5:BI$22) -> 15 | BK8: =VLOOKUP($A8,'2025'!$A:$IZ,176,FALSE) -> 32.36 | BL8: =RANK(BK8,BK$5:BK$22,1) -> 8 | BM8: =VLOOKUP($A8,'2025'!$A:$IZ,11,FALSE) -> 53.265 | BN8: =RANK(BM8,BM$5:BM$22) -> 2 | BO8: =VLOOKUP($A8,'2025'!$A:$IZ,222,FALSE) -> -1.4 | BP8: =RANK(BO8,BO$5:BO$22) -> 13 | BQ8: =106-(BF8+BH8+BN8+BP8+BJ8+BL8) -> 62 | BR8: =RANK(BQ8,BQ$5:BQ$22) -> 6 | BT8: =VLOOKUP($A8,'Ratings Season'!$A:$M,10,FALSE) -> 3.3 | BU8: =RANK(BT8,BT$5:BT$22) -> 8 | BV8: =VLOOKUP($A8,'Ratings Season'!$A:$M,12,FALSE) -> 14.3 | BW8: =RANK(BV8,BV$5:BV$22) -> 1 | BX8: =VLOOKUP($A8,'Ratings Season'!$A:$M,8,FALSE) -> 17.6 | BY8: =RANK(BX8,BX$5:BX$22) -> 5
A9: Essendon | B9: =VLOOKUP($A9,'2025'!$A:$IZ,222,FALSE) -> 0.522 | C9: =RANK(B9,B$5:B$22) -> 8 | D9: =VLOOKUP($A9,'2025'!$A:$IZ,218,FALSE) -> 1.565 | E9: =RANK(D9,D$5:D$22) -> 7 | F9: =VLOOKUP($A9,'2025'!$A:$IZ,49,FALSE) -> 74.505 | G9: =RANK(F9,F$5:F$22) -> 10 | H9: =VLOOKUP($A9,'2025'!$A:$IZ,229,FALSE) -> -1.174 | I9: =RANK(H9,H$5:H$22) -> 11 | J9: =104-(C9+E9+G9+I9) -> 68 | K9: =RANK(J9,J$5:J$22) -> 11 | M9: =VLOOKUP($A9,'2025'!$A:$IZ,88,FALSE) -> 10.392 | N9: =RANK(M9,M$5:M$22) -> 17 | O9: =VLOOKUP($A9,'2025'!$A:$IZ,84,FALSE) -> 17.543 | P9: =RANK(O9,O$5:O$22) -> 17 | Q9: =VLOOKUP($A9,'2025'!$A:$IZ,85,FALSE) -> 20.042 | R9: =RANK(Q9,Q$5:Q$22) -> 17 | S9: =VLOOKUP($A9,'2025'!$A:$IZ,29,FALSE) -> -2.285 | T9: =RANK(S9,S$5:S$22) -> 18 | U9: =104-(N9+P9+R9+T9) -> 35 | V9: =RANK(U9,U$5:U$22) -> 18 | X9: =VLOOKUP($A9,'2025'!$A:$IZ,65,FALSE) -> 40.428 | Y9: =RANK(X9,X$5:X$22) -> 17 | Z9: =VLOOKUP($A9,'2025'!$A:$IZ,64,FALSE) -> 20.446 | AA9: =RANK(Z9,Z$5:Z$22) -> 16 | AB9: =VLOOKUP($A9,'2025'!$A:$IZ,63,FALSE) -> 46.316 | AC9: =RANK(AB9,AB$5:AB$22) -> 13 | AD9: =VLOOKUP($A9,'2025'!$A:$IZ,71,FALSE) -> -1.429 | AE9: =RANK(AD9,AD$5:AD$22) -> 11 | AF9: =104-(Y9+AA9+AC9+AE9) -> 47 | AG9: =RANK(AF9,AF$5:AF$22) -> 15 | AI9: =VLOOKUP($A9,'2025'!$A:$IZ,183,FALSE) -> 13.373 | AJ9: =RANK(AI9,AI$5:AI$22,1) -> 18 | AK9: =VLOOKUP($A9,'2025'!$A:$IZ,181,FALSE) -> 23.324 | AL9: =RANK(AK9,AK$5:AK$22,1) -> 15 | AM9: =VLOOKUP($A9,'2025'!$A:$IZ,182,FALSE) -> 30.178 | AN9: =RANK(AM9,AM$5:AM$22,1) -> 18 | AO9: =VLOOKUP($A9,'2025'!$A:$IZ,163,FALSE) -> 25.817 | AP9: =RANK(AO9,AO$5:AO$22,1) -> 15 | AQ9: =104-(AJ9+AL9+AN9+AP9) -> 38 | AR9: =RANK(AQ9,AQ$5:AQ$22) -> 16 | AT9: =VLOOKUP($A9,'2025'!$A:$IZ,250,FALSE) -> 3.783 | AU9: =RANK(AT9,AT$5:AT$22,0) -> 3 | AV9: =VLOOKUP($A9,'2025'!$A:$IZ,92,FALSE) -> 8.783 | AW9: =RANK(AV9,AV$5:AV$22,0) -> 17 | AX9: =VLOOKUP($A9,'2025'!$A:$IZ,93,FALSE) -> 272.478 | AY9: =RANK(AX9,AX$5:AX$22,0) -> 5 | AZ9: =VLOOKUP($A9,'2025'!$A:$IZ,108,FALSE) -> 37.565 | BA9: =RANK(AZ9,AZ$5:AZ$22,0) -> 18 | BB9: =104-(AU9+AW9+AY9+BA9) -> 61 | BC9: =RANK(BB9,BB$5:BB$22) -> 12 | BE9: =VLOOKUP($A9,'2025'!$A:$IZ,80,FALSE) -> 36.957 | BF9: =RANK(BE9,BE$5:BE$22) -> 16 | BG9: =VLOOKUP($A9,'2025'!$A:$IZ,177,FALSE) -> 59.348 | BH9: =RANK(BG9,BG$5:BG$22,1) -> 17 | BI9: =VLOOKUP($A9,'2025'!$A:$IZ,79,FALSE) -> 26.826 | BJ9: =RANK(BI9,BI$5:BI$22) -> 16 | BK9: =VLOOKUP($A9,'2025'!$A:$IZ,176,FALSE) -> 31.652 | BL9: =RANK(BK9,BK$5:BK$22,1) -> 6 | BM9: =VLOOKUP($A9,'2025'!$A:$IZ,11,FALSE) -> 46.882 | BN9: =RANK(BM9,BM$5:BM$22) -> 15 | BO9: =VLOOKUP($A9,'2025'!$A:$IZ,222,FALSE) -> 0.522 | BP9: =RANK(BO9,BO$5:BO$22) -> 8 | BQ9: =106-(BF9+BH9+BN9+BP9+BJ9+BL9) -> 28 | BR9: =RANK(BQ9,BQ$5:BQ$22) -> 14 | BT9: =VLOOKUP($A9,'Ratings Season'!$A:$M,10,FALSE) -> -15.5 | BU9: =RANK(BT9,BT$5:BT$22) -> 16 | BV9: =VLOOKUP($A9,'Ratings Season'!$A:$M,12,FALSE) -> -8.3 | BW9: =RANK(BV9,BV$5:BV$22) -> 15 | BX9: =VLOOKUP($A9,'Ratings Season'!$A:$M,8,FALSE) -> -23.8 | BY9: =RANK(BX9,BX$5:BX$22) -> 16
A10: Fremantle | B10: =VLOOKUP($A10,'2025'!$A:$IZ,222,FALSE) -> -1.917 | C10: =RANK(B10,B$5:B$22) -> 14 | D10: =VLOOKUP($A10,'2025'!$A:$IZ,218,FALSE) -> -2.292 | E10: =RANK(D10,D$5:D$22) -> 14 | F10: =VLOOKUP($A10,'2025'!$A:$IZ,49,FALSE) -> 75.852 | G10: =RANK(F10,F$5:F$22) -> 7 | H10: =VLOOKUP($A10,'2025'!$A:$IZ,229,FALSE) -> 1.375 | I10: =RANK(H10,H$5:H$22) -> 7 | J10: =104-(C10+E10+G10+I10) -> 62 | K10: =RANK(J10,J$5:J$22) -> 13 | M10: =VLOOKUP($A10,'2025'!$A:$IZ,88,FALSE) -> 13.674 | N10: =RANK(M10,M$5:M$22) -> 7 | O10: =VLOOKUP($A10,'2025'!$A:$IZ,84,FALSE) -> 21.141 | P10: =RANK(O10,O$5:O$22) -> 8 | Q10: =VLOOKUP($A10,'2025'!$A:$IZ,85,FALSE) -> 21.099 | R10: =RANK(Q10,Q$5:Q$22) -> 11 | S10: =VLOOKUP($A10,'2025'!$A:$IZ,29,FALSE) -> -0.347 | T10: =RANK(S10,S$5:S$22) -> 12 | U10: =104-(N10+P10+R10+T10) -> 66 | V10: =RANK(U10,U$5:U$22) -> 10 | X10: =VLOOKUP($A10,'2025'!$A:$IZ,65,FALSE) -> 44.171 | Y10: =RANK(X10,X$5:X$22) -> 12 | Z10: =VLOOKUP($A10,'2025'!$A:$IZ,64,FALSE) -> 23.791 | AA10: =RANK(Z10,Z$5:Z$22) -> 8 | AB10: =VLOOKUP($A10,'2025'!$A:$IZ,63,FALSE) -> 48.94 | AC10: =RANK(AB10,AB$5:AB$22) -> 8 | AD10: =VLOOKUP($A10,'2025'!$A:$IZ,71,FALSE) -> -0.057 | AE10: =RANK(AD10,AD$5:AD$22) -> 8 | AF10: =104-(Y10+AA10+AC10+AE10) -> 68 | AG10: =RANK(AF10,AF$5:AF$22) -> 10 | AI10: =VLOOKUP($A10,'2025'!$A:$IZ,183,FALSE) -> 9.016 | AJ10: =RANK(AI10,AI$5:AI$22,1) -> 8 | AK10: =VLOOKUP($A10,'2025'!$A:$IZ,181,FALSE) -> 19.512 | AL10: =RANK(AK10,AK$5:AK$22,1) -> 8 | AM10: =VLOOKUP($A10,'2025'!$A:$IZ,182,FALSE) -> 20.829 | AN10: =RANK(AM10,AM$5:AM$22,1) -> 3 | AO10: =VLOOKUP($A10,'2025'!$A:$IZ,163,FALSE) -> 23.43 | AP10: =RANK(AO10,AO$5:AO$22,1) -> 9 | AQ10: =104-(AJ10+AL10+AN10+AP10) -> 76 | AR10: =RANK(AQ10,AQ$5:AQ$22) -> 6 | AT10: =VLOOKUP($A10,'2025'!$A:$IZ,250,FALSE) -> -4.25 | AU10: =RANK(AT10,AT$5:AT$22,0) -> 14 | AV10: =VLOOKUP($A10,'2025'!$A:$IZ,92,FALSE) -> 10.292 | AW10: =RANK(AV10,AV$5:AV$22,0) -> 13 | AX10: =VLOOKUP($A10,'2025'!$A:$IZ,93,FALSE) -> 262.25 | AY10: =RANK(AX10,AX$5:AX$22,0) -> 13 | AZ10: =VLOOKUP($A10,'2025'!$A:$IZ,108,FALSE) -> 45.125 | BA10: =RANK(AZ10,AZ$5:AZ$22,0) -> 3 | BB10: =104-(AU10+AW10+AY10+BA10) -> 61 | BC10: =RANK(BB10,BB$5:BB$22) -> 12 | BE10: =VLOOKUP($A10,'2025'!$A:$IZ,80,FALSE) -> 47.833 | BF10: =RANK(BE10,BE$5:BE$22) -> 9 | BG10: =VLOOKUP($A10,'2025'!$A:$IZ,177,FALSE) -> 43.5 | BH10: =RANK(BG10,BG$5:BG$22,1) -> 7 | BI10: =VLOOKUP($A10,'2025'!$A:$IZ,79,FALSE) -> 33.542 | BJ10: =RANK(BI10,BI$5:BI$22) -> 9 | BK10: =VLOOKUP($A10,'2025'!$A:$IZ,176,FALSE) -> 32.625 | BL10: =RANK(BK10,BK$5:BK$22,1) -> 9 | BM10: =VLOOKUP($A10,'2025'!$A:$IZ,11,FALSE) -> 49.844 | BN10: =RANK(BM10,BM$5:BM$22) -> 11 | BO10: =VLOOKUP($A10,'2025'!$A:$IZ,222,FALSE) -> -1.917 | BP10: =RANK(BO10,BO$5:BO$22) -> 14 | BQ10: =106-(BF10+BH10+BN10+BP10+BJ10+BL10) -> 47 | BR10: =RANK(BQ10,BQ$5:BQ$22) -> 11 | BT10: =VLOOKUP($A10,'Ratings Season'!$A:$M,10,FALSE) -> 0.3 | BU10: =RANK(BT10,BT$5:BT$22) -> 9 | BV10: =VLOOKUP($A10,'Ratings Season'!$A:$M,12,FALSE) -> 5.4 | BW10: =RANK(BV10,BV$5:BV$22) -> 7 | BX10: =VLOOKUP($A10,'Ratings Season'!$A:$M,8,FALSE) -> 5.7 | BY10: =RANK(BX10,BX$5:BX$22) -> 9
A11: Geelong | B11: =VLOOKUP($A11,'2025'!$A:$IZ,222,FALSE) -> 5.731 | C11: =RANK(B11,B$5:B$22) -> 2 | D11: =VLOOKUP($A11,'2025'!$A:$IZ,218,FALSE) -> 3.692 | E11: =RANK(D11,D$5:D$22) -> 3 | F11: =VLOOKUP($A11,'2025'!$A:$IZ,49,FALSE) -> 73.161 | G11: =RANK(F11,F$5:F$22) -> 14 | H11: =VLOOKUP($A11,'2025'!$A:$IZ,229,FALSE) -> 0.038 | I11: =RANK(H11,H$5:H$22) -> 10 | J11: =104-(C11+E11+G11+I11) -> 75 | K11: =RANK(J11,J$5:J$22) -> 5 | M11: =VLOOKUP($A11,'2025'!$A:$IZ,88,FALSE) -> 15.822 | N11: =RANK(M11,M$5:M$22) -> 2 | O11: =VLOOKUP($A11,'2025'!$A:$IZ,84,FALSE) -> 25.087 | P11: =RANK(O11,O$5:O$22) -> 2 | Q11: =VLOOKUP($A11,'2025'!$A:$IZ,85,FALSE) -> 28.661 | R11: =RANK(Q11,Q$5:Q$22) -> 1 | S11: =VLOOKUP($A11,'2025'!$A:$IZ,29,FALSE) -> 4.798 | T11: =RANK(S11,S$5:S$22) -> 1 | U11: =104-(N11+P11+R11+T11) -> 98 | V11: =RANK(U11,U$5:U$22) -> 1 | X11: =VLOOKUP($A11,'2025'!$A:$IZ,65,FALSE) -> 49.658 | Y11: =RANK(X11,X$5:X$22) -> 2 | Z11: =VLOOKUP($A11,'2025'!$A:$IZ,64,FALSE) -> 27.322 | AA11: =RANK(Z11,Z$5:Z$22) -> 2 | AB11: =VLOOKUP($A11,'2025'!$A:$IZ,63,FALSE) -> 51.086 | AC11: =RANK(AB11,AB$5:AB$22) -> 5 | AD11: =VLOOKUP($A11,'2025'!$A:$IZ,71,FALSE) -> 2.598 | AE11: =RANK(AD11,AD$5:AD$22) -> 4 | AF11: =104-(Y11+AA11+AC11+AE11) -> 91 | AG11: =RANK(AF11,AF$5:AF$22) -> 3 | AI11: =VLOOKUP($A11,'2025'!$A:$IZ,183,FALSE) -> 8.77 | AJ11: =RANK(AI11,AI$5:AI$22,1) -> 5 | AK11: =VLOOKUP($A11,'2025'!$A:$IZ,181,FALSE) -> 19.077 | AL11: =RANK(AK11,AK$5:AK$22,1) -> 4 | AM11: =VLOOKUP($A11,'2025'!$A:$IZ,182,FALSE) -> 22.476 | AN11: =RANK(AM11,AM$5:AM$22,1) -> 11 | AO11: =VLOOKUP($A11,'2025'!$A:$IZ,163,FALSE) -> 22.593 | AP11: =RANK(AO11,AO$5:AO$22,1) -> 6 | AQ11: =104-(AJ11+AL11+AN11+AP11) -> 78 | AR11: =RANK(AQ11,AQ$5:AQ$22) -> 4 | AT11: =VLOOKUP($A11,'2025'!$A:$IZ,250,FALSE) -> 2.385 | AU11: =RANK(AT11,AT$5:AT$22,0) -> 6 | AV11: =VLOOKUP($A11,'2025'!$A:$IZ,92,FALSE) -> 14.077 | AW11: =RANK(AV11,AV$5:AV$22,0) -> 1 | AX11: =VLOOKUP($A11,'2025'!$A:$IZ,93,FALSE) -> 278.615 | AY11: =RANK(AX11,AX$5:AX$22,0) -> 2 | AZ11: =VLOOKUP($A11,'2025'!$A:$IZ,108,FALSE) -> 39.385 | BA11: =RANK(AZ11,AZ$5:AZ$22,0) -> 17 | BB11: =104-(AU11+AW11+AY11+BA11) -> 78 | BC11: =RANK(BB11,BB$5:BB$22) -> 3 | BE11: =VLOOKUP($A11,'2025'!$A:$IZ,80,FALSE) -> 59.192 | BF11: =RANK(BE11,BE$5:BE$22) -> 1 | BG11: =VLOOKUP($A11,'2025'!$A:$IZ,177,FALSE) -> 41.808 | BH11: =RANK(BG11,BG$5:BG$22,1) -> 5 | BI11: =VLOOKUP($A11,'2025'!$A:$IZ,79,FALSE) -> 40.962 | BJ11: =RANK(BI11,BI$5:BI$22) -> 2 | BK11: =VLOOKUP($A11,'2025'!$A:$IZ,176,FALSE) -> 31.077 | BL11: =RANK(BK11,BK$5:BK$22,1) -> 5 | BM11: =VLOOKUP($A11,'2025'!$A:$IZ,11,FALSE) -> 53.19 | BN11: =RANK(BM11,BM$5:BM$22) -> 3 | BO11: =VLOOKUP($A11,'2025'!$A:$IZ,222,FALSE) -> 5.731 | BP11: =RANK(BO11,BO$5:BO$22) -> 2 | BQ11: =106-(BF11+BH11+BN11+BP11+BJ11+BL11) -> 88 | BR11: =RANK(BQ11,BQ$5:BQ$22) -> 1 | BT11: =VLOOKUP($A11,'Ratings Season'!$A:$M,10,FALSE) -> 19.2 | BU11: =RANK(BT11,BT$5:BT$22) -> 2 | BV11: =VLOOKUP($A11,'Ratings Season'!$A:$M,12,FALSE) -> 6.4 | BW11: =RANK(BV11,BV$5:BV$22) -> 6 | BX11: =VLOOKUP($A11,'Ratings Season'!$A:$M,8,FALSE) -> 25.6 | BY11: =RANK(BX11,BX$5:BX$22) -> 1
A12: Gold Coast | B12: =VLOOKUP($A12,'2025'!$A:$IZ,222,FALSE) -> -0.04 | C12: =RANK(B12,B$5:B$22) -> 10 | D12: =VLOOKUP($A12,'2025'!$A:$IZ,218,FALSE) -> -1.24 | E12: =RANK(D12,D$5:D$22) -> 13 | F12: =VLOOKUP($A12,'2025'!$A:$IZ,49,FALSE) -> 76.888 | G12: =RANK(F12,F$5:F$22) -> 2 | H12: =VLOOKUP($A12,'2025'!$A:$IZ,229,FALSE) -> 3.28 | I12: =RANK(H12,H$5:H$22) -> 4 | J12: =104-(C12+E12+G12+I12) -> 75 | K12: =RANK(J12,J$5:J$22) -> 5 | M12: =VLOOKUP($A12,'2025'!$A:$IZ,88,FALSE) -> 13.164 | N12: =RANK(M12,M$5:M$22) -> 8 | O12: =VLOOKUP($A12,'2025'!$A:$IZ,84,FALSE) -> 22.468 | P12: =RANK(O12,O$5:O$22) -> 3 | Q12: =VLOOKUP($A12,'2025'!$A:$IZ,85,FALSE) -> 24.867 | R12: =RANK(Q12,Q$5:Q$22) -> 6 | S12: =VLOOKUP($A12,'2025'!$A:$IZ,29,FALSE) -> 1.796 | T12: =RANK(S12,S$5:S$22) -> 6 | U12: =104-(N12+P12+R12+T12) -> 81 | V12: =RANK(U12,U$5:U$22) -> 5 | X12: =VLOOKUP($A12,'2025'!$A:$IZ,65,FALSE) -> 44.744 | Y12: =RANK(X12,X$5:X$22) -> 9 | Z12: =VLOOKUP($A12,'2025'!$A:$IZ,64,FALSE) -> 23.722 | AA12: =RANK(Z12,Z$5:Z$22) -> 9 | AB12: =VLOOKUP($A12,'2025'!$A:$IZ,63,FALSE) -> 50.226 | AC12: =RANK(AB12,AB$5:AB$22) -> 6 | AD12: =VLOOKUP($A12,'2025'!$A:$IZ,71,FALSE) -> 0.684 | AE12: =RANK(AD12,AD$5:AD$22) -> 6 | AF12: =104-(Y12+AA12+AC12+AE12) -> 74 | AG12: =RANK(AF12,AF$5:AF$22) -> 7 | AI12: =VLOOKUP($A12,'2025'!$A:$IZ,183,FALSE) -> 9.701 | AJ12: =RANK(AI12,AI$5:AI$22,1) -> 13 | AK12: =VLOOKUP($A12,'2025'!$A:$IZ,181,FALSE) -> 19.165 | AL12: =RANK(AK12,AK$5:AK$22,1) -> 5 | AM12: =VLOOKUP($A12,'2025'!$A:$IZ,182,FALSE) -> 23.579 | AN12: =RANK(AM12,AM$5:AM$22,1) -> 12 | AO12: =VLOOKUP($A12,'2025'!$A:$IZ,163,FALSE) -> 22.474 | AP12: =RANK(AO12,AO$5:AO$22,1) -> 5 | AQ12: =104-(AJ12+AL12+AN12+AP12) -> 69 | AR12: =RANK(AQ12,AQ$5:AQ$22) -> 10 | AT12: =VLOOKUP($A12,'2025'!$A:$IZ,250,FALSE) -> -3.88 | AU12: =RANK(AT12,AT$5:AT$22,0) -> 13 | AV12: =VLOOKUP($A12,'2025'!$A:$IZ,92,FALSE) -> 11.24 | AW12: =RANK(AV12,AV$5:AV$22,0) -> 8 | AX12: =VLOOKUP($A12,'2025'!$A:$IZ,93,FALSE) -> 266.56 | AY12: =RANK(AX12,AX$5:AX$22,0) -> 11 | AZ12: =VLOOKUP($A12,'2025'!$A:$IZ,108,FALSE) -> 47.52 | BA12: =RANK(AZ12,AZ$5:AZ$22,0) -> 1 | BB12: =104-(AU12+AW12+AY12+BA12) -> 71 | BC12: =RANK(BB12,BB$5:BB$22) -> 8 | BE12: =VLOOKUP($A12,'2025'!$A:$IZ,80,FALSE) -> 48.96 | BF12: =RANK(BE12,BE$5:BE$22) -> 8 | BG12: =VLOOKUP($A12,'2025'!$A:$IZ,177,FALSE) -> 43.04 | BH12: =RANK(BG12,BG$5:BG$22,1) -> 6 | BI12: =VLOOKUP($A12,'2025'!$A:$IZ,79,FALSE) -> 38.92 | BJ12: =RANK(BI12,BI$5:BI$22) -> 3 | BK12: =VLOOKUP($A12,'2025'!$A:$IZ,176,FALSE) -> 29.76 | BL12: =RANK(BK12,BK$5:BK$22,1) -> 2 | BM12: =VLOOKUP($A12,'2025'!$A:$IZ,11,FALSE) -> 52.922 | BN12: =RANK(BM12,BM$5:BM$22) -> 4 | BO12: =VLOOKUP($A12,'2025'!$A:$IZ,222,FALSE) -> -0.04 | BP12: =RANK(BO12,BO$5:BO$22) -> 10 | BQ12: =106-(BF12+BH12+BN12+BP12+BJ12+BL12) -> 73 | BR12: =RANK(BQ12,BQ$5:BQ$22) -> 4 | BT12: =VLOOKUP($A12,'Ratings Season'!$A:$M,10,FALSE) -> 8.4 | BU12: =RANK(BT12,BT$5:BT$22) -> 5 | BV12: =VLOOKUP($A12,'Ratings Season'!$A:$M,12,FALSE) -> 7.5 | BW12: =RANK(BV12,BV$5:BV$22) -> 5 | BX12: =VLOOKUP($A12,'Ratings Season'!$A:$M,8,FALSE) -> 15.9 | BY12: =RANK(BX12,BX$5:BX$22) -> 7
A13: Greater Western Sydney | B13: =VLOOKUP($A13,'2025'!$A:$IZ,222,FALSE) -> 0.417 | C13: =RANK(B13,B$5:B$22) -> 9 | D13: =VLOOKUP($A13,'2025'!$A:$IZ,218,FALSE) -> -0.333 | E13: =RANK(D13,D$5:D$22) -> 11 | F13: =VLOOKUP($A13,'2025'!$A:$IZ,49,FALSE) -> 75.812 | G13: =RANK(F13,F$5:F$22) -> 8 | H13: =VLOOKUP($A13,'2025'!$A:$IZ,229,FALSE) -> -2.083 | I13: =RANK(H13,H$5:H$22) -> 13 | J13: =104-(C13+E13+G13+I13) -> 63 | K13: =RANK(J13,J$5:J$22) -> 12 | M13: =VLOOKUP($A13,'2025'!$A:$IZ,88,FALSE) -> 13.959 | N13: =RANK(M13,M$5:M$22) -> 4 | O13: =VLOOKUP($A13,'2025'!$A:$IZ,84,FALSE) -> 21.369 | P13: =RANK(O13,O$5:O$22) -> 7 | Q13: =VLOOKUP($A13,'2025'!$A:$IZ,85,FALSE) -> 24.59 | R13: =RANK(Q13,Q$5:Q$22) -> 7 | S13: =VLOOKUP($A13,'2025'!$A:$IZ,29,FALSE) -> 2.175 | T13: =RANK(S13,S$5:S$22) -> 4 | U13: =104-(N13+P13+R13+T13) -> 82 | V13: =RANK(U13,U$5:U$22) -> 4 | X13: =VLOOKUP($A13,'2025'!$A:$IZ,65,FALSE) -> 46.57 | Y13: =RANK(X13,X$5:X$22) -> 3 | Z13: =VLOOKUP($A13,'2025'!$A:$IZ,64,FALSE) -> 26.231 | AA13: =RANK(Z13,Z$5:Z$22) -> 4 | AB13: =VLOOKUP($A13,'2025'!$A:$IZ,63,FALSE) -> 51.343 | AC13: =RANK(AB13,AB$5:AB$22) -> 4 | AD13: =VLOOKUP($A13,'2025'!$A:$IZ,71,FALSE) -> 4.308 | AE13: =RANK(AD13,AD$5:AD$22) -> 3 | AF13: =104-(Y13+AA13+AC13+AE13) -> 90 | AG13: =RANK(AF13,AF$5:AF$22) -> 4 | AI13: =VLOOKUP($A13,'2025'!$A:$IZ,183,FALSE) -> 8.215 | AJ13: =RANK(AI13,AI$5:AI$22,1) -> 2 | AK13: =VLOOKUP($A13,'2025'!$A:$IZ,181,FALSE) -> 21.055 | AL13: =RANK(AK13,AK$5:AK$22,1) -> 11 | AM13: =VLOOKUP($A13,'2025'!$A:$IZ,182,FALSE) -> 22.234 | AN13: =RANK(AM13,AM$5:AM$22,1) -> 9 | AO13: =VLOOKUP($A13,'2025'!$A:$IZ,163,FALSE) -> 20.553 | AP13: =RANK(AO13,AO$5:AO$22,1) -> 2 | AQ13: =104-(AJ13+AL13+AN13+AP13) -> 80 | AR13: =RANK(AQ13,AQ$5:AQ$22) -> 3 | AT13: =VLOOKUP($A13,'2025'!$A:$IZ,250,FALSE) -> 7.125 | AU13: =RANK(AT13,AT$5:AT$22,0) -> 2 | AV13: =VLOOKUP($A13,'2025'!$A:$IZ,92,FALSE) -> 10.583 | AW13: =RANK(AV13,AV$5:AV$22,0) -> 12 | AX13: =VLOOKUP($A13,'2025'!$A:$IZ,93,FALSE) -> 261.542 | AY13: =RANK(AX13,AX$5:AX$22,0) -> 15 | AZ13: =VLOOKUP($A13,'2025'!$A:$IZ,108,FALSE) -> 43.958 | BA13: =RANK(AZ13,AZ$5:AZ$22,0) -> 6 | BB13: =104-(AU13+AW13+AY13+BA13) -> 69 | BC13: =RANK(BB13,BB$5:BB$22) -> 9 | BE13: =VLOOKUP($A13,'2025'!$A:$IZ,80,FALSE) -> 49.292 | BF13: =RANK(BE13,BE$5:BE$22) -> 7 | BG13: =VLOOKUP($A13,'2025'!$A:$IZ,177,FALSE) -> 44.75 | BH13: =RANK(BG13,BG$5:BG$22,1) -> 10 | BI13: =VLOOKUP($A13,'2025'!$A:$IZ,79,FALSE) -> 36.542 | BJ13: =RANK(BI13,BI$5:BI$22) -> 5 | BK13: =VLOOKUP($A13,'2025'!$A:$IZ,176,FALSE) -> 33.75 | BL13: =RANK(BK13,BK$5:BK$22,1) -> 12 | BM13: =VLOOKUP($A13,'2025'!$A:$IZ,11,FALSE) -> 47.708 | BN13: =RANK(BM13,BM$5:BM$22) -> 14 | BO13: =VLOOKUP($A13,'2025'!$A:$IZ,222,FALSE) -> 0.417 | BP13: =RANK(BO13,BO$5:BO$22) -> 9 | BQ13: =106-(BF13+BH13+BN13+BP13+BJ13+BL13) -> 49 | BR13: =RANK(BQ13,BQ$5:BQ$22) -> 10 | BT13: =VLOOKUP($A13,'Ratings Season'!$A:$M,10,FALSE) -> 5.9 | BU13: =RANK(BT13,BT$5:BT$22) -> 7 | BV13: =VLOOKUP($A13,'Ratings Season'!$A:$M,12,FALSE) -> 1.2 | BW13: =RANK(BV13,BV$5:BV$22) -> 10 | BX13: =VLOOKUP($A13,'Ratings Season'!$A:$M,8,FALSE) -> 7.1 | BY13: =RANK(BX13,BX$5:BX$22) -> 8
A14: Hawthorn | B14: =VLOOKUP($A14,'2025'!$A:$IZ,222,FALSE) -> 5.038 | C14: =RANK(B14,B$5:B$22) -> 4 | D14: =VLOOKUP($A14,'2025'!$A:$IZ,218,FALSE) -> -0.192 | E14: =RANK(D14,D$5:D$22) -> 10 | F14: =VLOOKUP($A14,'2025'!$A:$IZ,49,FALSE) -> 73.567 | G14: =RANK(F14,F$5:F$22) -> 12 | H14: =VLOOKUP($A14,'2025'!$A:$IZ,229,FALSE) -> -2.654 | I14: =RANK(H14,H$5:H$22) -> 16 | J14: =104-(C14+E14+G14+I14) -> 62 | K14: =RANK(J14,J$5:J$22) -> 13 | M14: =VLOOKUP($A14,'2025'!$A:$IZ,88,FALSE) -> 13.141 | N14: =RANK(M14,M$5:M$22) -> 9 | O14: =VLOOKUP($A14,'2025'!$A:$IZ,84,FALSE) -> 20.794 | P14: =RANK(O14,O$5:O$22) -> 9 | Q14: =VLOOKUP($A14,'2025'!$A:$IZ,85,FALSE) -> 23.048 | R14: =RANK(Q14,Q$5:Q$22) -> 9 | S14: =VLOOKUP($A14,'2025'!$A:$IZ,29,FALSE) -> 3.272 | T14: =RANK(S14,S$5:S$22) -> 3 | U14: =104-(N14+P14+R14+T14) -> 74 | V14: =RANK(U14,U$5:U$22) -> 6 | X14: =VLOOKUP($A14,'2025'!$A:$IZ,65,FALSE) -> 45.309 | Y14: =RANK(X14,X$5:X$22) -> 5 | Z14: =VLOOKUP($A14,'2025'!$A:$IZ,64,FALSE) -> 24.945 | AA14: =RANK(Z14,Z$5:Z$22) -> 6 | AB14: =VLOOKUP($A14,'2025'!$A:$IZ,63,FALSE) -> 50.146 | AC14: =RANK(AB14,AB$5:AB$22) -> 7 | AD14: =VLOOKUP($A14,'2025'!$A:$IZ,71,FALSE) -> 2.396 | AE14: =RANK(AD14,AD$5:AD$22) -> 5 | AF14: =104-(Y14+AA14+AC14+AE14) -> 81 | AG14: =RANK(AF14,AF$5:AF$22) -> 5 | AI14: =VLOOKUP($A14,'2025'!$A:$IZ,183,FALSE) -> 8.829 | AJ14: =RANK(AI14,AI$5:AI$22,1) -> 6 | AK14: =VLOOKUP($A14,'2025'!$A:$IZ,181,FALSE) -> 18.739 | AL14: =RANK(AK14,AK$5:AK$22,1) -> 3 | AM14: =VLOOKUP($A14,'2025'!$A:$IZ,182,FALSE) -> 20.714 | AN14: =RANK(AM14,AM$5:AM$22,1) -> 2 | AO14: =VLOOKUP($A14,'2025'!$A:$IZ,163,FALSE) -> 20.942 | AP14: =RANK(AO14,AO$5:AO$22,1) -> 3 | AQ14: =104-(AJ14+AL14+AN14+AP14) -> 90 | AR14: =RANK(AQ14,AQ$5:AQ$22) -> 2 | AT14: =VLOOKUP($A14,'2025'!$A:$IZ,250,FALSE) -> -4.346 | AU14: =RANK(AT14,AT$5:AT$22,0) -> 15 | AV14: =VLOOKUP($A14,'2025'!$A:$IZ,92,FALSE) -> 11.692 | AW14: =RANK(AV14,AV$5:AV$22,0) -> 5 | AX14: =VLOOKUP($A14,'2025'!$A:$IZ,93,FALSE) -> 278.654 | AY14: =RANK(AX14,AX$5:AX$22,0) -> 1 | AZ14: =VLOOKUP($A14,'2025'!$A:$IZ,108,FALSE) -> 43.192 | BA14: =RANK(AZ14,AZ$5:AZ$22,0) -> 9 | BB14: =104-(AU14+AW14+AY14+BA14) -> 74 | BC14: =RANK(BB14,BB$5:BB$22) -> 4 | BE14: =VLOOKUP($A14,'2025'!$A:$IZ,80,FALSE) -> 49.346 | BF14: =RANK(BE14,BE$5:BE$22) -> 6 | BG14: =VLOOKUP($A14,'2025'!$A:$IZ,177,FALSE) -> 38.962 | BH14: =RANK(BG14,BG$5:BG$22,1) -> 2 | BI14: =VLOOKUP($A14,'2025'!$A:$IZ,79,FALSE) -> 36.077 | BJ14: =RANK(BI14,BI$5:BI$22) -> 6 | BK14: =VLOOKUP($A14,'2025'!$A:$IZ,176,FALSE) -> 33.077 | BL14: =RANK(BK14,BK$5:BK$22,1) -> 10 | BM14: =VLOOKUP($A14,'2025'!$A:$IZ,11,FALSE) -> 51.059 | BN14: =RANK(BM14,BM$5:BM$22) -> 8 | BO14: =VLOOKUP($A14,'2025'!$A:$IZ,222,FALSE) -> 5.038 | BP14: =RANK(BO14,BO$5:BO$22) -> 4 | BQ14: =106-(BF14+BH14+BN14+BP14+BJ14+BL14) -> 70 | BR14: =RANK(BQ14,BQ$5:BQ$22) -> 5 | BT14: =VLOOKUP($A14,'Ratings Season'!$A:$M,10,FALSE) -> 6.9 | BU14: =RANK(BT14,BT$5:BT$22) -> 6 | BV14: =VLOOKUP($A14,'Ratings Season'!$A:$M,12,FALSE) -> 9.2 | BW14: =RANK(BV14,BV$5:BV$22) -> 3 | BX14: =VLOOKUP($A14,'Ratings Season'!$A:$M,8,FALSE) -> 16.1 | BY14: =RANK(BX14,BX$5:BX$22) -> 6
A15: Melbourne | B15: =VLOOKUP($A15,'2025'!$A:$IZ,222,FALSE) -> 5.304 | C15: =RANK(B15,B$5:B$22) -> 3 | D15: =VLOOKUP($A15,'2025'!$A:$IZ,218,FALSE) -> 2.652 | E15: =RANK(D15,D$5:D$22) -> 6 | F15: =VLOOKUP($A15,'2025'!$A:$IZ,49,FALSE) -> 72.325 | G15: =RANK(F15,F$5:F$22) -> 16 | H15: =VLOOKUP($A15,'2025'!$A:$IZ,229,FALSE) -> 0.957 | I15: =RANK(H15,H$5:H$22) -> 9 | J15: =104-(C15+E15+G15+I15) -> 70 | K15: =RANK(J15,J$5:J$22) -> 9 | M15: =VLOOKUP($A15,'2025'!$A:$IZ,88,FALSE) -> 12.595 | N15: =RANK(M15,M$5:M$22) -> 12 | O15: =VLOOKUP($A15,'2025'!$A:$IZ,84,FALSE) -> 21.468 | P15: =RANK(O15,O$5:O$22) -> 6 | Q15: =VLOOKUP($A15,'2025'!$A:$IZ,85,FALSE) -> 24.085 | R15: =RANK(Q15,Q$5:Q$22) -> 8 | S15: =VLOOKUP($A15,'2025'!$A:$IZ,29,FALSE) -> 1.325 | T15: =RANK(S15,S$5:S$22) -> 9 | U15: =104-(N15+P15+R15+T15) -> 69 | V15: =RANK(U15,U$5:U$22) -> 8 | X15: =VLOOKUP($A15,'2025'!$A:$IZ,65,FALSE) -> 45.058 | Y15: =RANK(X15,X$5:X$22) -> 7 | Z15: =VLOOKUP($A15,'2025'!$A:$IZ,64,FALSE) -> 22.323 | AA15: =RANK(Z15,Z$5:Z$22) -> 12 | AB15: =VLOOKUP($A15,'2025'!$A:$IZ,63,FALSE) -> 44.572 | AC15: =RANK(AB15,AB$5:AB$22) -> 16 | AD15: =VLOOKUP($A15,'2025'!$A:$IZ,71,FALSE) -> -3.635 | AE15: =RANK(AD15,AD$5:AD$22) -> 17 | AF15: =104-(Y15+AA15+AC15+AE15) -> 52 | AG15: =RANK(AF15,AF$5:AF$22) -> 12 | AI15: =VLOOKUP($A15,'2025'!$A:$IZ,183,FALSE) -> 10.182 | AJ15: =RANK(AI15,AI$5:AI$22,1) -> 14 | AK15: =VLOOKUP($A15,'2025'!$A:$IZ,181,FALSE) -> 21.208 | AL15: =RANK(AK15,AK$5:AK$22,1) -> 12 | AM15: =VLOOKUP($A15,'2025'!$A:$IZ,182,FALSE) -> 24.064 | AN15: =RANK(AM15,AM$5:AM$22,1) -> 13 | AO15: =VLOOKUP($A15,'2025'!$A:$IZ,163,FALSE) -> 26.572 | AP15: =RANK(AO15,AO$5:AO$22,1) -> 16 | AQ15: =104-(AJ15+AL15+AN15+AP15) -> 49 | AR15: =RANK(AQ15,AQ$5:AQ$22) -> 14 | AT15: =VLOOKUP($A15,'2025'!$A:$IZ,250,FALSE) -> 2.696 | AU15: =RANK(AT15,AT$5:AT$22,0) -> 5 | AV15: =VLOOKUP($A15,'2025'!$A:$IZ,92,FALSE) -> 11.435 | AW15: =RANK(AV15,AV$5:AV$22,0) -> 7 | AX15: =VLOOKUP($A15,'2025'!$A:$IZ,93,FALSE) -> 261.739 | AY15: =RANK(AX15,AX$5:AX$22,0) -> 14 | AZ15: =VLOOKUP($A15,'2025'!$A:$IZ,108,FALSE) -> 40.565 | BA15: =RANK(AZ15,AZ$5:AZ$22,0) -> 12 | BB15: =104-(AU15+AW15+AY15+BA15) -> 66 | BC15: =RANK(BB15,BB$5:BB$22) -> 11 | BE15: =VLOOKUP($A15,'2025'!$A:$IZ,80,FALSE) -> 45.174 | BF15: =RANK(BE15,BE$5:BE$22) -> 11 | BG15: =VLOOKUP($A15,'2025'!$A:$IZ,177,FALSE) -> 48.261 | BH15: =RANK(BG15,BG$5:BG$22,1) -> 12 | BI15: =VLOOKUP($A15,'2025'!$A:$IZ,79,FALSE) -> 32.913 | BJ15: =RANK(BI15,BI$5:BI$22) -> 10 | BK15: =VLOOKUP($A15,'2025'!$A:$IZ,176,FALSE) -> 35.391 | BL15: =RANK(BK15,BK$5:BK$22,1) -> 13 | BM15: =VLOOKUP($A15,'2025'!$A:$IZ,11,FALSE) -> 51.448 | BN15: =RANK(BM15,BM$5:BM$22) -> 5 | BO15: =VLOOKUP($A15,'2025'!$A:$IZ,222,FALSE) -> 5.304 | BP15: =RANK(BO15,BO$5:BO$22) -> 3 | BQ15: =106-(BF15+BH15+BN15+BP15+BJ15+BL15) -> 52 | BR15: =RANK(BQ15,BQ$5:BQ$22) -> 9 | BT15: =VLOOKUP($A15,'Ratings Season'!$A:$M,10,FALSE) -> -0.8 | BU15: =RANK(BT15,BT$5:BT$22) -> 10 | BV15: =VLOOKUP($A15,'Ratings Season'!$A:$M,12,FALSE) -> -2.9 | BW15: =RANK(BV15,BV$5:BV$22) -> 12 | BX15: =VLOOKUP($A15,'Ratings Season'!$A:$M,8,FALSE) -> -3.7 | BY15: =RANK(BX15,BX$5:BX$22) -> 12
A16: North Melbourne | B16: =VLOOKUP($A16,'2025'!$A:$IZ,222,FALSE) -> -5.087 | C16: =RANK(B16,B$5:B$22) -> 15 | D16: =VLOOKUP($A16,'2025'!$A:$IZ,218,FALSE) -> 0.652 | E16: =RANK(D16,D$5:D$22) -> 8 | F16: =VLOOKUP($A16,'2025'!$A:$IZ,49,FALSE) -> 76.131 | G16: =RANK(F16,F$5:F$22) -> 6 | H16: =VLOOKUP($A16,'2025'!$A:$IZ,229,FALSE) -> 2.609 | I16: =RANK(H16,H$5:H$22) -> 6 | J16: =104-(C16+E16+G16+I16) -> 69 | K16: =RANK(J16,J$5:J$22) -> 10 | M16: =VLOOKUP($A16,'2025'!$A:$IZ,88,FALSE) -> 10.385 | N16: =RANK(M16,M$5:M$22) -> 18 | O16: =VLOOKUP($A16,'2025'!$A:$IZ,84,FALSE) -> 18.814 | P16: =RANK(O16,O$5:O$22) -> 15 | Q16: =VLOOKUP($A16,'2025'!$A:$IZ,85,FALSE) -> 19.393 | R16: =RANK(Q16,Q$5:Q$22) -> 18 | S16: =VLOOKUP($A16,'2025'!$A:$IZ,29,FALSE) -> -0.573 | T16: =RANK(S16,S$5:S$22) -> 14 | U16: =104-(N16+P16+R16+T16) -> 39 | V16: =RANK(U16,U$5:U$22) -> 16 | X16: =VLOOKUP($A16,'2025'!$A:$IZ,65,FALSE) -> 44.34 | Y16: =RANK(X16,X$5:X$22) -> 11 | Z16: =VLOOKUP($A16,'2025'!$A:$IZ,64,FALSE) -> 25.189 | AA16: =RANK(Z16,Z$5:Z$22) -> 5 | AB16: =VLOOKUP($A16,'2025'!$A:$IZ,63,FALSE) -> 51.445 | AC16: =RANK(AB16,AB$5:AB$22) -> 3 | AD16: =VLOOKUP($A16,'2025'!$A:$IZ,71,FALSE) -> -0.111 | AE16: =RANK(AD16,AD$5:AD$22) -> 9 | AF16: =104-(Y16+AA16+AC16+AE16) -> 76 | AG16: =RANK(AF16,AF$5:AF$22) -> 6 | AI16: =VLOOKUP($A16,'2025'!$A:$IZ,183,FALSE) -> 12.341 | AJ16: =RANK(AI16,AI$5:AI$22,1) -> 15 | AK16: =VLOOKUP($A16,'2025'!$A:$IZ,181,FALSE) -> 25.485 | AL16: =RANK(AK16,AK$5:AK$22,1) -> 18 | AM16: =VLOOKUP($A16,'2025'!$A:$IZ,182,FALSE) -> 26.845 | AN16: =RANK(AM16,AM$5:AM$22,1) -> 16 | AO16: =VLOOKUP($A16,'2025'!$A:$IZ,163,FALSE) -> 27.067 | AP16: =RANK(AO16,AO$5:AO$22,1) -> 17 | AQ16: =104-(AJ16+AL16+AN16+AP16) -> 38 | AR16: =RANK(AQ16,AQ$5:AQ$22) -> 16 | AT16: =VLOOKUP($A16,'2025'!$A:$IZ,250,FALSE) -> -5.87 | AU16: =RANK(AT16,AT$5:AT$22,0) -> 16 | AV16: =VLOOKUP($A16,'2025'!$A:$IZ,92,FALSE) -> 10.652 | AW16: =RANK(AV16,AV$5:AV$22,0) -> 11 | AX16: =VLOOKUP($A16,'2025'!$A:$IZ,93,FALSE) -> 261.087 | AY16: =RANK(AX16,AX$5:AX$22,0) -> 16 | AZ16: =VLOOKUP($A16,'2025'!$A:$IZ,108,FALSE) -> 39.957 | BA16: =RANK(AZ16,AZ$5:AZ$22,0) -> 15 | BB16: =104-(AU16+AW16+AY16+BA16) -> 46 | BC16: =RANK(BB16,BB$5:BB$22) -> 18 | BE16: =VLOOKUP($A16,'2025'!$A:$IZ,80,FALSE) -> 35.739 | BF16: =RANK(BE16,BE$5:BE$22) -> 17 | BG16: =VLOOKUP($A16,'2025'!$A:$IZ,177,FALSE) -> 55.87 | BH16: =RANK(BG16,BG$5:BG$22,1) -> 16 | BI16: =VLOOKUP($A16,'2025'!$A:$IZ,79,FALSE) -> 37.783 | BJ16: =RANK(BI16,BI$5:BI$22) -> 4 | BK16: =VLOOKUP($A16,'2025'!$A:$IZ,176,FALSE) -> 42.348 | BL16: =RANK(BK16,BK$5:BK$22,1) -> 18 | BM16: =VLOOKUP($A16,'2025'!$A:$IZ,11,FALSE) -> 45.872 | BN16: =RANK(BM16,BM$5:BM$22) -> 18 | BO16: =VLOOKUP($A16,'2025'!$A:$IZ,222,FALSE) -> -5.087 | BP16: =RANK(BO16,BO$5:BO$22) -> 15 | BQ16: =106-(BF16+BH16+BN16+BP16+BJ16+BL16) -> 18 | BR16: =RANK(BQ16,BQ$5:BQ$22) -> 15 | BT16: =VLOOKUP($A16,'Ratings Season'!$A:$M,10,FALSE) -> -5.3 | BU16: =RANK(BT16,BT$5:BT$22) -> 13 | BV16: =VLOOKUP($A16,'Ratings Season'!$A:$M,12,FALSE) -> -16.1 | BW16: =RANK(BV16,BV$5:BV$22) -> 17 | BX16: =VLOOKUP($A16,'Ratings Season'!$A:$M,8,FALSE) -> -21.4 | BY16: =RANK(BX16,BX$5:BX$22) -> 15
... A22: Western Bulldogs | B22: =VLOOKUP($A22,'2025'!$A:$IZ,222,FALSE) -> 1.609 | C22: =RANK(B22,B$5:B$22) -> 6 | D22: =VLOOKUP($A22,'2025'!$A:$IZ,218,FALSE) -> 6.435 | E22: =RANK(D22,D$5:D$22) -> 2 | F22: =VLOOKUP($A22,'2025'!$A:$IZ,49,FALSE) -> 78.014 | G22: =RANK(F22,F$5:F$22) -> 1 | H22: =VLOOKUP($A22,'2025'!$A:$IZ,229,FALSE) -> 5.87 | I22: =RANK(H22,H$5:H$22) -> 1 | J22: =104-(C22+E22+G22+I22) -> 94 | K22: =RANK(J22,J$5:J$22) -> 1 | M22: =VLOOKUP($A22,'2025'!$A:$IZ,88,FALSE) -> 15.994 | N22: =RANK(M22,M$5:M$22) -> 1 | O22: =VLOOKUP($A22,'2025'!$A:$IZ,84,FALSE) -> 25.307 | P22: =RANK(O22,O$5:O$22) -> 1 | Q22: =VLOOKUP($A22,'2025'!$A:$IZ,85,FALSE) -> 27.636 | R22: =RANK(Q22,Q$5:Q$22) -> 2 | S22: =VLOOKUP($A22,'2025'!$A:$IZ,29,FALSE) -> 4.269 | T22: =RANK(S22,S$5:S$22) -> 2 | U22: =104-(N22+P22+R22+T22) -> 98 | V22: =RANK(U22,U$5:U$22) -> 1 | X22: =VLOOKUP($A22,'2025'!$A:$IZ,65,FALSE) -> 49.923 | Y22: =RANK(X22,X$5:X$22) -> 1 | Z22: =VLOOKUP($A22,'2025'!$A:$IZ,64,FALSE) -> 28.428 | AA22: =RANK(Z22,Z$5:Z$22) -> 1 | AB22: =VLOOKUP($A22,'2025'!$A:$IZ,63,FALSE) -> 53.324 | AC22: =RANK(AB22,AB$5:AB$22) -> 1 | AD22: =VLOOKUP($A22,'2025'!$A:$IZ,71,FALSE) -> 4.494 | AE22: =RANK(AD22,AD$5:AD$22) -> 2 | AF22: =104-(Y22+AA22+AC22+AE22) -> 99 | AG22: =RANK(AF22,AF$5:AF$22) -> 1 | AI22: =VLOOKUP($A22,'2025'!$A:$IZ,183,FALSE) -> 9.332 | AJ22: =RANK(AI22,AI$5:AI$22,1) -> 10 | AK22: =VLOOKUP($A22,'2025'!$A:$IZ,181,FALSE) -> 19.967 | AL22: =RANK(AK22,AK$5:AK$22,1) -> 9 | AM22: =VLOOKUP($A22,'2025'!$A:$IZ,182,FALSE) -> 21.103 | AN22: =RANK(AM22,AM$5:AM$22,1) -> 4 | AO22: =VLOOKUP($A22,'2025'!$A:$IZ,163,FALSE) -> 24.223 | AP22: =RANK(AO22,AO$5:AO$22,1) -> 10 | AQ22: =104-(AJ22+AL22+AN22+AP22) -> 71 | AR22: =RANK(AQ22,AQ$5:AQ$22) -> 9 | AT22: =VLOOKUP($A22,'2025'!$A:$IZ,250,FALSE) -> -6.696 | AU22: =RANK(AT22,AT$5:AT$22,0) -> 17 | AV22: =VLOOKUP($A22,'2025'!$A:$IZ,92,FALSE) -> 12.174 | AW22: =RANK(AV22,AV$5:AV$22,0) -> 3 | AX22: =VLOOKUP($A22,'2025'!$A:$IZ,93,FALSE) -> 266.783 | AY22: =RANK(AX22,AX$5:AX$22,0) -> 10 | AZ22: =VLOOKUP($A22,'2025'!$A:$IZ,108,FALSE) -> 43.87 | BA22: =RANK(AZ22,AZ$5:AZ$22,0) -> 7 | BB22: =104-(AU22+AW22+AY22+BA22) -> 67 | BC22: =RANK(BB22,BB$5:BB$22) -> 10 | BE22: =VLOOKUP($A22,'2025'!$A:$IZ,80,FALSE) -> 55.739 | BF22: =RANK(BE22,BE$5:BE$22) -> 3 | BG22: =VLOOKUP($A22,'2025'!$A:$IZ,177,FALSE) -> 44.13 | BH22: =RANK(BG22,BG$5:BG$22,1) -> 9 | BI22: =VLOOKUP($A22,'2025'!$A:$IZ,79,FALSE) -> 47.565 | BJ22: =RANK(BI22,BI$5:BI$22) -> 1 | BK22: =VLOOKUP($A22,'2025'!$A:$IZ,176,FALSE) -> 30.087 | BL22: =RANK(BK22,BK$5:BK$22,1) -> 3 | BM22: =VLOOKUP($A22,'2025'!$A:$IZ,11,FALSE) -> 54.035 | BN22: =RANK(BM22,BM$5:BM$22) -> 1 | BO22: =VLOOKUP($A22,'2025'!$A:$IZ,222,FALSE) -> 1.609 | BP22: =RANK(BO22,BO$5:BO$22) -> 6 | BQ22: =106-(BF22+BH22+BN22+BP22+BJ22+BL22) -> 83 | BR22: =RANK(BQ22,BQ$5:BQ$22) -> 2 | BT22: =VLOOKUP($A22,'Ratings Season'!$A:$M,10,FALSE) -> 21.5 | BU22: =RANK(BT22,BT$5:BT$22) -> 1 | BV22: =VLOOKUP($A22,'Ratings Season'!$A:$M,12,FALSE) -> 3.7 | BW22: =RANK(BV22,BV$5:BV$22) -> 9 | BX22: =VLOOKUP($A22,'Ratings Season'!$A:$M,8,FALSE) -> 25.2 | BY22: =RANK(BX22,BX$5:BX$22) -> 2
A24: LAST 10 GAMES
A26: Team | B26: Ball Winning | M26: Ball Movement | X26: Scoring | AI26: Defence | AT26: Pressure | BE26: Health Check | BT26: Wheelo Ratings
B27: Post Clear CP Diff | C27: Rank | D27: Ground Ball Diff | E27: Rank | F27: 1st Poss to Clear % | G27: Rank | H27: Clearance Diff | I27: Rank | J27: Ball Winning Ranking | K27: Rank | M27: Def Half to Score % | N27: Rank | O27: Chain to Score % | P27: Rank | Q27: D50 to F50 % | R27: Rank | S27: Kick Rating | T27: Rank | U27: Ball Movement Ranking | V27: Rank | X27: Scores per I50 % | Y27: Rank | Z27: Goals Per I 50 % | AA27: Rank | AB27: Accuracy % | AC27: Rank | AD27: +/- Exp Score | AE27: Rank | AF27: Scoring Ranking | AG27: Rank | AI27: Def Half to Score Ag % | AJ27: Rank | AK27: Chain to Score Ag % | AL27: Rank | AM27: D50 to F50 Ag % | AN27: Rank | AO27: Goals Per I50 Ag % | AP27: Rank | AQ27: Defence Ranking | AR27: Rank | AT27: Tackle Diff | AU27: Rank | AV27: F50 Tackles | AW27: Rank | AX27: Pressure Acts | AY27: Rank | AZ27: 1%'ers | BA27: Rank | BB27: Pressure Ranking | BC27: Rank | BE27: Score from Turnover For | BF27: Rank | BG27: Scores from Turnover Ag | BH27: Rank | BI27: Scores from Stoppages For | BJ27: Rank | BK27: Scores from Stoppage Ag | BL27: Rank | BM27: Territory % | BN27: Rank | BO27: Post-Clearance CP Diff | BP27: Rank | BQ27: Health Check Ranking | BR27: Rank | BT27: Attack Rating | BU27: Rank | BV27: Defence Rating | BW27: Rank | BX27: Overall Rating | BY27: Rank
A28: Adelaide | B28: =VLOOKUP($A28,'L10'!$A:$IZ,222,FALSE) -> 6.2 | C28: =RANK(B28,B$28:B$45) -> 4 | D28: =VLOOKUP($A28,'L10'!$A:$IZ,218,FALSE) -> -4.2 | E28: =RANK(D28,D$28:D$45) -> 13 | F28: =VLOOKUP($A28,'L10'!$A:$IZ,49,FALSE) -> 76.962 | G28: =RANK(F28,F$28:F$45) -> 4 | H28: =VLOOKUP($A28,'L10'!$A:$IZ,229,FALSE) -> -3.3 | I28: =RANK(H28,H$28:H$45) -> 14 | J28: =104-(C28+E28+G28+I28) -> 69 | K28: =RANK(J28,J$28:J$45) -> 11 | M28: =VLOOKUP($A28,'L10'!$A:$IZ,88,FALSE) -> 12.429 | N28: =RANK(M28,M$28:M$45) -> 10 | O28: =VLOOKUP($A28,'L10'!$A:$IZ,84,FALSE) -> 20.208 | P28: =RANK(O28,O$28:O$45) -> 11 | Q28: =VLOOKUP($A28,'L10'!$A:$IZ,85,FALSE) -> 20.256 | R28: =RANK(Q28,Q$28:Q$45) -> 16 | S28: =VLOOKUP($A28,'L10'!$A:$IZ,29,FALSE) -> 1.314 | T28: =RANK(S28,S$28:S$45) -> 7 | U28: =104-(N28+P28+R28+T28) -> 60 | V28: =RANK(U28,U$28:U$45) -> 10 | X28: =VLOOKUP($A28,'L10'!$A:$IZ,65,FALSE) -> 46.918 | Y28: =RANK(X28,X$28:X$45) -> 5 | Z28: =VLOOKUP($A28,'L10'!$A:$IZ,64,FALSE) -> 27.237 | AA28: =RANK(Z28,Z$28:Z$45) -> 4 | AB28: =VLOOKUP($A28,'L10'!$A:$IZ,63,FALSE) -> 53.725 | AC28: =RANK(AB28,AB$28:AB$45) -> 2 | AD28: =VLOOKUP($A28,'L10'!$A:$IZ,71,FALSE) -> 7.524 | AE28: =RANK(AD28,AD$28:AD$45) -> 1 | AF28: =104-(Y28+AA28+AC28+AE28) -> 92 | AG28: =RANK(AF28,AF$28:AF$45) -> 3 | AI28: =VLOOKUP($A28,'L10'!$A:$IZ,183,FALSE) -> 6.077 | AJ28: =RANK(AI28,AI$28:AI$45,1) -> 1 | AK28: =VLOOKUP($A28,'L10'!$A:$IZ,181,FALSE) -> 17.637 | AL28: =RANK(AK28,AK$28:AK$45,1) -> 2 | AM28: =VLOOKUP($A28,'L10'!$A:$IZ,182,FALSE) -> 15.702 | AN28: =RANK(AM28,AM$28:AM$45,1) -> 1 | AO28: =VLOOKUP($A28,'L10'!$A:$IZ,163,FALSE) -> 21.401 | AP28: =RANK(AO28,AO$28:AO$45,1) -> 3 | AQ28: =104-(AJ28+AL28+AN28+AP28) -> 97 | AR28: =RANK(AQ28,AQ$28:AQ$45) -> 1 | AT28: =VLOOKUP($A28,'L10'!$A:$IZ,250,FALSE) -> 0.5 | AU28: =RANK(AT28,AT$28:AT$45,0) -> 10 | AV28: =VLOOKUP($A28,'L10'!$A:$IZ,92,FALSE) -> 8.1 | AW28: =RANK(AV28,AV$28:AV$45,0) -> 17 | AX28: =VLOOKUP($A28,'L10'!$A:$IZ,93,FALSE) -> 276.8 | AY28: =RANK(AX28,AX$28:AX$45,0) -> 3 | AZ28: =VLOOKUP($A28,'L10'!$A:$IZ,108,FALSE) -> 46 | BA28: =RANK(AZ28,AZ$28:AZ$45,0) -> 4 | BB28: =104-(AU28+AW28+AY28+BA28) -> 70 | BC28: =RANK(BB28,BB$28:BB$45,0) -> 5 | BE28: =VLOOKUP($A28,'L10'!$A:$IZ,80,FALSE) -> 52.3 | BF28: =RANK(BE28,BE$28:BE$45) -> 4 | BG28: =VLOOKUP($A28,'L10'!$A:$IZ,177,FALSE) -> 40.9 | BH28: =RANK(BG28,BG$28:BG$45,1) -> 5 | BI28: =VLOOKUP($A28,'L10'!$A:$IZ,79,FALSE) -> 36 | BJ28: =RANK(BI28,BI$28:BI$45) -> 8 | BK28: =VLOOKUP($A28,'L10'!$A:$IZ,176,FALSE) -> 31.5 | BL28: =RANK(BK28,BK$28:BK$45,1) -> 5 | BM28: =VLOOKUP($A28,'L10'!$A:$IZ,11,FALSE) -> 49.913 | BN28: =RANK(BM28,BM$28:BM$45) -> 9 | BO28: =VLOOKUP($A28,'L10'!$A:$IZ,222,FALSE) -> 6.2 | BP28: =RANK(BO28,BO$28:BO$45) -> 4 | BQ28: =104-(BJ28+BL28+BN28+BP28) -> 78 | BR28: =RANK(BQ28,BQ$28:BQ$45) -> 5 | BT28: =VLOOKUP($A28,'Ratings Season'!$A:$M,8,FALSE) -> 18.2 | BU28: =RANK(BT28,BT$28:BT$45) -> 4 | BV28: =VLOOKUP($A28,'Ratings Season'!$A:$M,4,FALSE) -> 5.4 | BW28: =RANK(BV28,BV$28:BV$45) -> 7 | BX28: =VLOOKUP($A28,'Ratings Season'!$A:$M,2,FALSE) -> 11.5 | BY28: =RANK(BX28,BX$28:BX$45) -> 6
A29: Brisbane | B29: =VLOOKUP($A29,'L10'!$A:$IZ,222,FALSE) -> -0.8 | C29: =RANK(B29,B$28:B$45) -> 10 | D29: =VLOOKUP($A29,'L10'!$A:$IZ,218,FALSE) -> 5.1 | E29: =RANK(D29,D$28:D$45) -> 5 | F29: =VLOOKUP($A29,'L10'!$A:$IZ,49,FALSE) -> 74.889 | G29: =RANK(F29,F$28:F$45) -> 8 | H29: =VLOOKUP($A29,'L10'!$A:$IZ,229,FALSE) -> 6.9 | I29: =RANK(H29,H$28:H$45) -> 1 | J29: =104-(C29+E29+G29+I29) -> 80 | K29: =RANK(J29,J$28:J$45) -> 3 | M29: =VLOOKUP($A29,'L10'!$A:$IZ,88,FALSE) -> 13.162 | N29: =RANK(M29,M$28:M$45) -> 9 | O29: =VLOOKUP($A29,'L10'!$A:$IZ,84,FALSE) -> 21.862 | P29: =RANK(O29,O$28:O$45) -> 6 | Q29: =VLOOKUP($A29,'L10'!$A:$IZ,85,FALSE) -> 26.952 | R29: =RANK(Q29,Q$28:Q$45) -> 4 | S29: =VLOOKUP($A29,'L10'!$A:$IZ,29,FALSE) -> 1.2 | T29: =RANK(S29,S$28:S$45) -> 10 | U29: =104-(N29+P29+R29+T29) -> 75 | V29: =RANK(U29,U$28:U$45) -> 7 | X29: =VLOOKUP($A29,'L10'!$A:$IZ,65,FALSE) -> 45.026 | Y29: =RANK(X29,X$28:X$45) -> 11 | Z29: =VLOOKUP($A29,'L10'!$A:$IZ,64,FALSE) -> 23.037 | AA29: =RANK(Z29,Z$28:Z$45) -> 12 | AB29: =VLOOKUP($A29,'L10'!$A:$IZ,63,FALSE) -> 45.833 | AC29: =RANK(AB29,AB$28:AB$45) -> 12 | AD29: =VLOOKUP($A29,'L10'!$A:$IZ,71,FALSE) -> -0.934 | AE29: =RANK(AD29,AD$28:AD$45) -> 10 | AF29: =104-(Y29+AA29+AC29+AE29) -> 59 | AG29: =RANK(AF29,AF$28:AF$45) -> 11 | AI29: =VLOOKUP($A29,'L10'!$A:$IZ,183,FALSE) -> 9.524 | AJ29: =RANK(AI29,AI$28:AI$45,1) -> 8 | AK29: =VLOOKUP($A29,'L10'!$A:$IZ,181,FALSE) -> 19.404 | AL29: =RANK(AK29,AK$28:AK$45,1) -> 5 | AM29: =VLOOKUP($A29,'L10'!$A:$IZ,182,FALSE) -> 25.397 | AN29: =RANK(AM29,AM$28:AM$45,1) -> 13 | AO29: =VLOOKUP($A29,'L10'!$A:$IZ,163,FALSE) -> 22.158 | AP29: =RANK(AO29,AO$28:AO$45,1) -> 4 | AQ29: =104-(AJ29+AL29+AN29+AP29) -> 74 | AR29: =RANK(AQ29,AQ$28:AQ$45) -> 8 | AT29: =VLOOKUP($A29,'L10'!$A:$IZ,250,FALSE) -> 1.5 | AU29: =RANK(AT29,AT$28:AT$45,0) -> 8 | AV29: =VLOOKUP($A29,'L10'!$A:$IZ,92,FALSE) -> 12.1 | AW29: =RANK(AV29,AV$28:AV$45,0) -> 5 | AX29: =VLOOKUP($A29,'L10'!$A:$IZ,93,FALSE) -> 266.6 | AY29: =RANK(AX29,AX$28:AX$45,0) -> 9 | AZ29: =VLOOKUP($A29,'L10'!$A:$IZ,108,FALSE) -> 48.5 | BA29: =RANK(AZ29,AZ$28:AZ$45,0) -> 1 | BB29: =104-(AU29+AW29+AY29+BA29) -> 81 | BC29: =RANK(BB29,BB$28:BB$45,0) -> 3 | BE29: =VLOOKUP($A29,'L10'!$A:$IZ,80,FALSE) -> 52.1 | BF29: =RANK(BE29,BE$28:BE$45) -> 5 | BG29: =VLOOKUP($A29,'L10'!$A:$IZ,177,FALSE) -> 39.5 | BH29: =RANK(BG29,BG$28:BG$45,1) -> 3 | BI29: =VLOOKUP($A29,'L10'!$A:$IZ,79,FALSE) -> 36.2 | BJ29: =RANK(BI29,BI$28:BI$45) -> 7 | BK29: =VLOOKUP($A29,'L10'!$A:$IZ,176,FALSE) -> 34.4 | BL29: =RANK(BK29,BK$28:BK$45,1) -> 9 | BM29: =VLOOKUP($A29,'L10'!$A:$IZ,11,FALSE) -> 50.249 | BN29: =RANK(BM29,BM$28:BM$45) -> 7 | BO29: =VLOOKUP($A29,'L10'!$A:$IZ,222,FALSE) -> -0.8 | BP29: =RANK(BO29,BO$28:BO$45) -> 10 | BQ29: =104-(BJ29+BL29+BN29+BP29) -> 71 | BR29: =RANK(BQ29,BQ$28:BQ$45) -> 9 | BT29: =VLOOKUP($A29,'Ratings Season'!$A:$M,8,FALSE) -> 18.8 | BU29: =RANK(BT29,BT$28:BT$45) -> 3 | BV29: =VLOOKUP($A29,'Ratings Season'!$A:$M,4,FALSE) -> 13.2 | BW29: =RANK(BV29,BV$28:BV$45) -> 3 | BX29: =VLOOKUP($A29,'Ratings Season'!$A:$M,2,FALSE) -> 26.3 | BY29: =RANK(BX29,BX$28:BX$45) -> 3
A30: Carlton | B30: =VLOOKUP($A30,'L10'!$A:$IZ,222,FALSE) -> -0.7 | C30: =RANK(B30,B$28:B$45) -> 9 | D30: =VLOOKUP($A30,'L10'!$A:$IZ,218,FALSE) -> 3.5 | E30: =RANK(D30,D$28:D$45) -> 6 | F30: =VLOOKUP($A30,'L10'!$A:$IZ,49,FALSE) -> 74.246 | G30: =RANK(F30,F$28:F$45) -> 12 | H30: =VLOOKUP($A30,'L10'!$A:$IZ,229,FALSE) -> 4.9 | I30: =RANK(H30,H$28:H$45) -> 3 | J30: =104-(C30+E30+G30+I30) -> 74 | K30: =RANK(J30,J$28:J$45) -> 5 | M30: =VLOOKUP($A30,'L10'!$A:$IZ,88,FALSE) -> 10.985 | N30: =RANK(M30,M$28:M$45) -> 15 | O30: =VLOOKUP($A30,'L10'!$A:$IZ,84,FALSE) -> 18.919 | P30: =RANK(O30,O$28:O$45) -> 14 | Q30: =VLOOKUP($A30,'L10'!$A:$IZ,85,FALSE) -> 23.611 | R30: =RANK(Q30,Q$28:Q$45) -> 8 | S30: =VLOOKUP($A30,'L10'!$A:$IZ,29,FALSE) -> -2.173 | T30: =RANK(S30,S$28:S$45) -> 15 | U30: =104-(N30+P30+R30+T30) -> 52 | V30: =RANK(U30,U$28:U$45) -> 13 | X30: =VLOOKUP($A30,'L10'!$A:$IZ,65,FALSE) -> 40.954 | Y30: =RANK(X30,X$28:X$45) -> 14 | Z30: =VLOOKUP($A30,'L10'!$A:$IZ,64,FALSE) -> 21.471 | AA30: =RANK(Z30,Z$28:Z$45) -> 14 | AB30: =VLOOKUP($A30,'L10'!$A:$IZ,63,FALSE) -> 47.368 | AC30: =RANK(AB30,AB$28:AB$45) -> 10 | AD30: =VLOOKUP($A30,'L10'!$A:$IZ,71,FALSE) -> -2.659 | AE30: =RANK(AD30,AD$28:AD$45) -> 15 | AF30: =104-(Y30+AA30+AC30+AE30) -> 51 | AG30: =RANK(AF30,AF$28:AF$45) -> 13 | AI30: =VLOOKUP($A30,'L10'!$A:$IZ,183,FALSE) -> 9.62 | AJ30: =RANK(AI30,AI$28:AI$45,1) -> 9 | AK30: =VLOOKUP($A30,'L10'!$A:$IZ,181,FALSE) -> 21.241 | AL30: =RANK(AK30,AK$28:AK$45,1) -> 10 | AM30: =VLOOKUP($A30,'L10'!$A:$IZ,182,FALSE) -> 25.253 | AN30: =RANK(AM30,AM$28:AM$45,1) -> 12 | AO30: =VLOOKUP($A30,'L10'!$A:$IZ,163,FALSE) -> 26.008 | AP30: =RANK(AO30,AO$28:AO$45,1) -> 14 | AQ30: =104-(AJ30+AL30+AN30+AP30) -> 59 | AR30: =RANK(AQ30,AQ$28:AQ$45) -> 12 | AT30: =VLOOKUP($A30,'L10'!$A:$IZ,250,FALSE) -> -1.1 | AU30: =RANK(AT30,AT$28:AT$45,0) -> 11 | AV30: =VLOOKUP($A30,'L10'!$A:$IZ,92,FALSE) -> 10.1 | AW30: =RANK(AV30,AV$28:AV$45,0) -> 13 | AX30: =VLOOKUP($A30,'L10'!$A:$IZ,93,FALSE) -> 274.9 | AY30: =RANK(AX30,AX$28:AX$45,0) -> 6 | AZ30: =VLOOKUP($A30,'L10'!$A:$IZ,108,FALSE) -> 41.8 | BA30: =RANK(AZ30,AZ$28:AZ$45,0) -> 11 | BB30: =104-(AU30+AW30+AY30+BA30) -> 63 | BC30: =RANK(BB30,BB$28:BB$45,0) -> 10 | BE30: =VLOOKUP($A30,'L10'!$A:$IZ,80,FALSE) -> 41.1 | BF30: =RANK(BE30,BE$28:BE$45) -> 13 | BG30: =VLOOKUP($A30,'L10'!$A:$IZ,177,FALSE) -> 45.2 | BH30: =RANK(BG30,BG$28:BG$45,1) -> 9 | BI30: =VLOOKUP($A30,'L10'!$A:$IZ,79,FALSE) -> 31 | BJ30: =RANK(BI30,BI$28:BI$45) -> 13 | BK30: =VLOOKUP($A30,'L10'!$A:$IZ,176,FALSE) -> 37.7 | BL30: =RANK(BK30,BK$28:BK$45,1) -> 14 | BM30: =VLOOKUP($A30,'L10'!$A:$IZ,11,FALSE) -> 49.757 | BN30: =RANK(BM30,BM$28:BM$45) -> 10 | BO30: =VLOOKUP($A30,'L10'!$A:$IZ,222,FALSE) -> -0.7 | BP30: =RANK(BO30,BO$28:BO$45) -> 9 | BQ30: =104-(BJ30+BL30+BN30+BP30) -> 58 | BR30: =RANK(BQ30,BQ$28:BQ$45) -> 12 | BT30: =VLOOKUP($A30,'Ratings Season'!$A:$M,8,FALSE) -> -2.6 | BU30: =RANK(BT30,BT$28:BT$45) -> 10 | BV30: =VLOOKUP($A30,'Ratings Season'!$A:$M,4,FALSE) -> -6.4 | BW30: =RANK(BV30,BV$28:BV$45) -> 13 | BX30: =VLOOKUP($A30,'Ratings Season'!$A:$M,2,FALSE) -> -3.3 | BY30: =RANK(BX30,BX$28:BX$45) -> 12
A31: Collingwood | B31: =VLOOKUP($A31,'L10'!$A:$IZ,222,FALSE) -> -2.2 | C31: =RANK(B31,B$28:B$45) -> 13 | D31: =VLOOKUP($A31,'L10'!$A:$IZ,218,FALSE) -> -8.1 | E31: =RANK(D31,D$28:D$45) -> 16 | F31: =VLOOKUP($A31,'L10'!$A:$IZ,49,FALSE) -> 69.014 | G31: =RANK(F31,F$28:F$45) -> 18 | H31: =VLOOKUP($A31,'L10'!$A:$IZ,229,FALSE) -> -4.6 | I31: =RANK(H31,H$28:H$45) -> 16 | J31: =104-(C31+E31+G31+I31) -> 41 | K31: =RANK(J31,J$28:J$45) -> 17 | M31: =VLOOKUP($A31,'L10'!$A:$IZ,88,FALSE) -> 10.169 | N31: =RANK(M31,M$28:M$45) -> 16 | O31: =VLOOKUP($A31,'L10'!$A:$IZ,84,FALSE) -> 19.283 | P31: =RANK(O31,O$28:O$45) -> 13 | Q31: =VLOOKUP($A31,'L10'!$A:$IZ,85,FALSE) -> 24.581 | R31: =RANK(Q31,Q$28:Q$45) -> 7 | S31: =VLOOKUP($A31,'L10'!$A:$IZ,29,FALSE) -> -3.601 | T31: =RANK(S31,S$28:S$45) -> 18 | U31: =104-(N31+P31+R31+T31) -> 50 | V31: =RANK(U31,U$28:U$45) -> 15 | X31: =VLOOKUP($A31,'L10'!$A:$IZ,65,FALSE) -> 40.074 | Y31: =RANK(X31,X$28:X$45) -> 16 | Z31: =VLOOKUP($A31,'L10'!$A:$IZ,64,FALSE) -> 19.485 | AA31: =RANK(Z31,Z$28:Z$45) -> 16 | AB31: =VLOOKUP($A31,'L10'!$A:$IZ,63,FALSE) -> 44.538 | AC31: =RANK(AB31,AB$28:AB$45) -> 16 | AD31: =VLOOKUP($A31,'L10'!$A:$IZ,71,FALSE) -> 0.934 | AE31: =RANK(AD31,AD$28:AD$45) -> 6 | AF31: =104-(Y31+AA31+AC31+AE31) -> 50 | AG31: =RANK(AF31,AF$28:AF$45) -> 14 | AI31: =VLOOKUP($A31,'L10'!$A:$IZ,183,FALSE) -> 8.916 | AJ31: =RANK(AI31,AI$28:AI$45,1) -> 4 | AK31: =VLOOKUP($A31,'L10'!$A:$IZ,181,FALSE) -> 17.186 | AL31: =RANK(AK31,AK$28:AK$45,1) -> 1 | AM31: =VLOOKUP($A31,'L10'!$A:$IZ,182,FALSE) -> 20.241 | AN31: =RANK(AM31,AM$28:AM$45,1) -> 2 | AO31: =VLOOKUP($A31,'L10'!$A:$IZ,163,FALSE) -> 23.779 | AP31: =RANK(AO31,AO$28:AO$45,1) -> 8 | AQ31: =104-(AJ31+AL31+AN31+AP31) -> 89 | AR31: =RANK(AQ31,AQ$28:AQ$45) -> 3 | AT31: =VLOOKUP($A31,'L10'!$A:$IZ,250,FALSE) -> 10.1 | AU31: =RANK(AT31,AT$28:AT$45,0) -> 1 | AV31: =VLOOKUP($A31,'L10'!$A:$IZ,92,FALSE) -> 15.2 | AW31: =RANK(AV31,AV$28:AV$45,0) -> 1 | AX31: =VLOOKUP($A31,'L10'!$A:$IZ,93,FALSE) -> 280.1 | AY31: =RANK(AX31,AX$28:AX$45,0) -> 2 | AZ31: =VLOOKUP($A31,'L10'!$A:$IZ,108,FALSE) -> 44.3 | BA31: =RANK(AZ31,AZ$28:AZ$45,0) -> 6 | BB31: =104-(AU31+AW31+AY31+BA31) -> 94 | BC31: =RANK(BB31,BB$28:BB$45,0) -> 1 | BE31: =VLOOKUP($A31,'L10'!$A:$IZ,80,FALSE) -> 42.8 | BF31: =RANK(BE31,BE$28:BE$45) -> 11 | BG31: =VLOOKUP($A31,'L10'!$A:$IZ,177,FALSE) -> 35.4 | BH31: =RANK(BG31,BG$28:BG$45,1) -> 1 | BI31: =VLOOKUP($A31,'L10'!$A:$IZ,79,FALSE) -> 29.4 | BJ31: =RANK(BI31,BI$28:BI$45) -> 15 | BK31: =VLOOKUP($A31,'L10'!$A:$IZ,176,FALSE) -> 37.7 | BL31: =RANK(BK31,BK$28:BK$45,1) -> 14 | BM31: =VLOOKUP($A31,'L10'!$A:$IZ,11,FALSE) -> 53.392 | BN31: =RANK(BM31,BM$28:BM$45) -> 3 | BO31: =VLOOKUP($A31,'L10'!$A:$IZ,222,FALSE) -> -2.2 | BP31: =RANK(BO31,BO$28:BO$45) -> 13 | BQ31: =104-(BJ31+BL31+BN31+BP31) -> 59 | BR31: =RANK(BQ31,BQ$28:BQ$45) -> 10 | BT31: =VLOOKUP($A31,'Ratings Season'!$A:$M,8,FALSE) -> 17.6 | BU31: =RANK(BT31,BT$28:BT$45) -> 5 | BV31: =VLOOKUP($A31,'Ratings Season'!$A:$M,4,FALSE) -> -0.4 | BW31: =RANK(BV31,BV$28:BV$45) -> 9 | BX31: =VLOOKUP($A31,'Ratings Season'!$A:$M,2,FALSE) -> 12.2 | BY31: =RANK(BX31,BX$28:BX$45) -> 5
A32: Essendon | B32: =VLOOKUP($A32,'L10'!$A:$IZ,222,FALSE) -> -1.1 | C32: =RANK(B32,B$28:B$45) -> 11 | D32: =VLOOKUP($A32,'L10'!$A:$IZ,218,FALSE) -> 1.8 | E32: =RANK(D32,D$28:D$45) -> 10 | F32: =VLOOKUP($A32,'L10'!$A:$IZ,49,FALSE) -> 74.432 | G32: =RANK(F32,F$28:F$45) -> 10 | H32: =VLOOKUP($A32,'L10'!$A:$IZ,229,FALSE) -> -6.4 | I32: =RANK(H32,H$28:H$45) -> 17 | J32: =104-(C32+E32+G32+I32) -> 56 | K32: =RANK(J32,J$28:J$45) -> 14 | M32: =VLOOKUP($A32,'L10'!$A:$IZ,88,FALSE) -> 9.248 | N32: =RANK(M32,M$28:M$45) -> 18 | O32: =VLOOKUP($A32,'L10'!$A:$IZ,84,FALSE) -> 17.191 | P32: =RANK(O32,O$28:O$45) -> 16 | Q32: =VLOOKUP($A32,'L10'!$A:$IZ,85,FALSE) -> 20.698 | R32: =RANK(Q32,Q$28:Q$45) -> 13 | S32: =VLOOKUP($A32,'L10'!$A:$IZ,29,FALSE) -> -2.752 | T32: =RANK(S32,S$28:S$45) -> 16 | U32: =104-(N32+P32+R32+T32) -> 41 | V32: =RANK(U32,U$28:U$45) -> 17 | X32: =VLOOKUP($A32,'L10'!$A:$IZ,65,FALSE) -> 37.953 | Y32: =RANK(X32,X$28:X$45) -> 17 | Z32: =VLOOKUP($A32,'L10'!$A:$IZ,64,FALSE) -> 17.484 | AA32: =RANK(Z32,Z$28:Z$45) -> 18 | AB32: =VLOOKUP($A32,'L10'!$A:$IZ,63,FALSE) -> 43.158 | AC32: =RANK(AB32,AB$28:AB$45) -> 18 | AD32: =VLOOKUP($A32,'L10'!$A:$IZ,71,FALSE) -> -5.038 | AE32: =RANK(AD32,AD$28:AD$45) -> 17 | AF32: =104-(Y32+AA32+AC32+AE32) -> 34 | AG32: =RANK(AF32,AF$28:AF$45) -> 18 | AI32: =VLOOKUP($A32,'L10'!$A:$IZ,183,FALSE) -> 13.089 | AJ32: =RANK(AI32,AI$28:AI$45,1) -> 16 | AK32: =VLOOKUP($A32,'L10'!$A:$IZ,181,FALSE) -> 24.004 | AL32: =RANK(AK32,AK$28:AK$45,1) -> 15 | AM32: =VLOOKUP($A32,'L10'!$A:$IZ,182,FALSE) -> 31.152 | AN32: =RANK(AM32,AM$28:AM$45,1) -> 18 | AO32: =VLOOKUP($A32,'L10'!$A:$IZ,163,FALSE) -> 27.289 | AP32: =RANK(AO32,AO$28:AO$45,1) -> 16 | AQ32: =104-(AJ32+AL32+AN32+AP32) -> 39 | AR32: =RANK(AQ32,AQ$28:AQ$45) -> 16 | AT32: =VLOOKUP($A32,'L10'!$A:$IZ,250,FALSE) -> 3.6 | AU32: =RANK(AT32,AT$28:AT$45,0) -> 3 | AV32: =VLOOKUP($A32,'L10'!$A:$IZ,92,FALSE) -> 10.3 | AW32: =RANK(AV32,AV$28:AV$45,0) -> 11 | AX32: =VLOOKUP($A32,'L10'!$A:$IZ,93,FALSE) -> 276.3 | AY32: =RANK(AX32,AX$28:AX$45,0) -> 4 | AZ32: =VLOOKUP($A32,'L10'!$A:$IZ,108,FALSE) -> 34.5 | BA32: =RANK(AZ32,AZ$28:AZ$45,0) -> 18 | BB32: =104-(AU32+AW32+AY32+BA32) -> 68 | BC32: =RANK(BB32,BB$28:BB$45,0) -> 7 | BE32: =VLOOKUP($A32,'L10'!$A:$IZ,80,FALSE) -> 33.5 | BF32: =RANK(BE32,BE$28:BE$45) -> 16 | BG32: =VLOOKUP($A32,'L10'!$A:$IZ,177,FALSE) -> 61.8 | BH32: =RANK(BG32,BG$28:BG$45,1) -> 17 | BI32: =VLOOKUP($A32,'L10'!$A:$IZ,79,FALSE) -> 21.1 | BJ32: =RANK(BI32,BI$28:BI$45) -> 17 | BK32: =VLOOKUP($A32,'L10'!$A:$IZ,176,FALSE) -> 34.9 | BL32: =RANK(BK32,BK$28:BK$45,1) -> 10 | BM32: =VLOOKUP($A32,'L10'!$A:$IZ,11,FALSE) -> 46.783 | BN32: =RANK(BM32,BM$28:BM$45) -> 15 | BO32: =VLOOKUP($A32,'L10'!$A:$IZ,222,FALSE) -> -1.1 | BP32: =RANK(BO32,BO$28:BO$45) -> 11 | BQ32: =104-(BJ32+BL32+BN32+BP32) -> 51 | BR32: =RANK(BQ32,BQ$28:BQ$45) -> 14 | BT32: =VLOOKUP($A32,'Ratings Season'!$A:$M,8,FALSE) -> -23.8 | BU32: =RANK(BT32,BT$28:BT$45) -> 16 | BV32: =VLOOKUP($A32,'Ratings Season'!$A:$M,4,FALSE) -> -16.6 | BW32: =RANK(BV32,BV$28:BV$45) -> 16 | BX32: =VLOOKUP($A32,'Ratings Season'!$A:$M,2,FALSE) -> -28 | BY32: =RANK(BX32,BX$28:BX$45) -> 16
